Workbook

Sheet 进度统计表
A1: 车控车设 | B1: 总接口量 | C1: =SUM('【对接进度说明】'!E2:E70) | H1: =G5+G12 | I1: 7 | J1: =H1/I1
C2: 已完成/已通过 | D2: 待完成/待通过 | E2: 总进度百分比 | F2: 生产率（条/人天） | G2: 剩余工期（人天） | H2: 合计剩余工作量 | I2: 可用人力 （已协调人力） | J2: 无任何阻塞所需工期
B3: 上汽适配接口提供 | C3: =SUM('【对接进度说明】'!I2:I70) | D3: =C1-C3 | E3: =C3/$C$1
B4: 上汽实车能力提供 | C4: =SUM('【对接进度说明】'!K2:J70) | D4: ='【对接进度说明】'!P65:P64 | E4: =C4/$C$1
B5: 火山开发适配 | C5: =SUM('【对接进度说明】'!T2:T70) | D5: =C1-C5 | E5: =C5/$C$1 | F5: 4 | G5: =D5/F5
B6: 上汽+火山测试执行 | C6: =SUM('【对接进度说明】'!AC2:AC70) | D6: =C1-C6 | E6: =C6/$C$1
B7: 火山测试执行 | C7: =C6-C8 | D7: =D6-D8 | E7: =C7/$C$1
B8: 上汽测试执行 | C8: ='【对接进度说明】'!AB66:AB65 | D8: ='【对接进度说明】'!AC66:AC65 | E8: =C8/$C$1
B9: 测试通过case | C9: =SUM('【对接进度说明】'!AI2:AI70) | D9: =C1-C9 | E9: =C9/$C$1
A11: 端状态 | B11: 总接口数量 | C11: 225
B12: 火山开发适配 | C12: 161 | D12: =C11-C12 | E12: =C12/C11 | F12: 6 | G12: =D12/F12
B13: 火山测试执行 | C13: 16 | D13: =C11-C13 | E13: =C13/C11
E15: 当前负责人 | I15: 当前卡点
C16: 数量 | D16: 比例 | E16: 上汽 | F16: 产品 | G16: 研发 | H16: 测试 | I16: 接口没提供 | J16: 接口
B17: 总api数
B18: 上汽提供api
B19: 研发验证
B20: 研发接
B21: 测试执行
B22: 测试通过

Sheet 透视表
A1: 车控 | D1: 系统设置 | G1: 通讯 | J1: 智能驾驶 | M1: 多媒体 | N1: ❌ | P1: 地图导航 | S1: 手车互联 | V1: 通用 | Y1: 模块 | Z1: 功能名称 | AA1: 主开发 （service逻辑+上汽原子能力）
Y2: 车控 | Z2: 车窗 | AA2: 余明明
Y3: 车控 | Z3: 空调 | AA3: 赵明珠
Y4: 车控 | Z4: 电动出风口 | AA4: 赵明珠
Y5: 车控 | Z5: 座椅 | AA5: 陈果果
Y6: 车控 | Z6: 外后视镜 | AA6: 谢一鸣
Y7: 车控 | Z7: 尾门 | AA7: 谢一鸣
Y8: 车控 | Z8: 雨刮 | AA8: 谢一鸣
Y9: 车控 | Z9: 遮阳帘 | AA9: 余明明
Y10: 车控 | Z10: 门锁 | AA10: 刘敬思
Y11: 车控 | Z11: 充电管理 | AA11: 陈果果
Y12: 车控 | Z12: 冰箱 | AA12: 杨忠谕
A13: 1 | Y13: 车控 | Z13: 晕动舒缓显示 | AA13: 余明明
A14: 模块\API（04.29变更前） | B14: 总api数 | C14: 本项目使用api数 | D14: 上汽已提供api数 | E14: 研发确认可用api数 | F14: 研发完成api数 | G14: 研发完成度 | H14: 测试覆盖api数 | I14: 测试执行完成度 | J14: 测试通过case数 | K14: case通过完成度 | L14: 备注
A15: 车控 | B15: 410 | C15: 400 | D15: 400 | E15: 392 | F15: 382 | G15: 0.955 | H15: 367 | I15: 0.9175 | J15: 335 | K15: 0.8375
A16: 系统设置 | B16: 126 | C16: 111 | D16: 106 | E16: 105 | F16: 101 | G16: 0.90990991 | H16: 79 | I16: 0.71171171 | J16: 68 | K16: 0.61261261
A17: 通讯 | B17: 26 | C17: 26 | D17: 26 | E17: 26 | F17: 23 | G17: 0.88461538 | H17: 24 | I17: 0.92307692 | J17: 24 | K17: 0.92307692
A18: 智能驾驶 | B18: 12 | C18: 7 | D18: 7 | E18: 5 | F18: 4 | G18: 0.57142857 | H18: 1 | I18: 0.14285714 | J18: 1 | K18: 0.14285714
A19: 多媒体 | B19: 81 | C19: 80 | D19: 80 | E19: 79 | F19: 78 | G19: 0.975 | H19: 75 | I19: 0.9375 | J19: 56 | K19: 0.7
A20: 地图导航 | B20: 69 | C20: 69 | D20: 69 | E20: 59 | F20: 59 | G20: 0.85507246 | H20: 61 | I20: 0.88405797 | J20: 37 | K20: 0.53623188 | L20: 不含AInavi
A21: 手车互联 | B21: 8 | C21: 8 | D21: 8 | E21: 0 | F21: 0 | G21: 0 | H21: 0 | I21: 0 | J21: 0 | K21: 0
A22: 通用 | B22: 3 | C22: 3 | D22: 3 | E22: 3 | F22: 3 | G22: 1 | H22: 3 | I22: 1 | J22: 1 | K22: 0.33333333
B23: 735 | C23: 704 | D23: 699 | E23: 669 | F23: 650 | G23: 0.92329545 | H23: 610 | I23: 0.86647727 | J23: 522 | K23: 0.74147727
A24: 端状态信号 | B24: 391 | C24: 241 | D24: 236 | E24: 208 | F24: 208 | G24: 0.86307054 | H24: 188 | I24: 0.78008299 | J24: 153 | K24: 0.63485477 | L24: 字节侧依赖： 1、阅读灯+系统和设置相关的信号共9个，依赖P基线的实车。 2、道路导航相关的，拥堵、沿途服务区，相关的API上汽已提供 3、媒体播放2个，演员+导演名字，验证不通过； 4、智驾相关的，当前不具备验证条件； 无依赖进展： 1、道路导航相关的正在开发； 2、较多的异常信号，实车没有对应的信号block测试（47）；除去block通过率在：73%左右。
A27: 46209
A28: 模块\API（04.29变更前） | B28: 总api数 | C28: 本项目使用api数 | D28: 上汽已提供api数 | E28: 研发确认可用api数 | F28: 研发完成api数 | G28: 研发完成度 | H28: 测试覆盖api数 | I28: 测试执行完成度 | J28: 测试通过case数 | K28: case通过完成度 | L28: 备注
A29: 车控 | B29: 410 | C29: 400 | D29: 400 | E29: 392 | F29: 382 | G29: 0.955 | H29: 367 | I29: 0.9175 | J29: 331 | K29: 0.8275
A30: 系统设置 | B30: 126 | C30: 111 | D30: 106 | E30: 105 | F30: 101 | G30: 0.90990991 | H30: 79 | I30: 0.71171171 | J30: 68 | K30: 0.61261261
A31: 通讯 | B31: 26 | C31: 26 | D31: 26 | E31: 26 | F31: 23 | G31: 0.88461538 | H31: 24 | I31: 0.92307692 | J31: 24 | K31: 0.92307692
A32: 智能驾驶 | B32: 12 | C32: 7 | D32: 7 | E32: 5 | F32: 4 | G32: 0.57142857 | H32: 1 | I32: 0.14285714 | J32: 1 | K32: 0.14285714
A33: 多媒体 | B33: 81 | C33: 80 | D33: 80 | E33: 79 | F33: 78 | G33: 0.975 | H33: 75 | I33: 0.9375 | J33: 56 | K33: 0.7
A34: 地图导航 | B34: 69 | C34: 69 | D34: 69 | E34: 59 | F34: 59 | G34: 0.85507246 | H34: 61 | I34: 0.88405797 | J34: 37 | K34: 0.53623188 | L34: 不含AInavi
A35: 手车互联 | B35: 8 | C35: 8 | D35: 8 | E35: 0 | F35: 0 | G35: 0 | H35: 0 | I35: 0 | J35: 0 | K35: 0
A36: 通用 | B36: 3 | C36: 3 | D36: 3 | E36: 3 | F36: 3 | G36: 1 | H36: 3 | I36: 1 | J36: 1 | K36: 0.33333333
B37: 735 | C37: 704 | D37: 699 | E37: 669 | F37: 650 | G37: 0.92329545 | H37: 610 | I37: 0.86647727 | J37: 518 | K37: 0.73579545
A38: 端状态信号 | B38: 391 | C38: 241 | D38: 236 | E38: 208 | F38: 208 | G38: 0.86307054 | H38: 188 | I38: 0.78008299 | J38: 153 | K38: 0.63485477 | L38: 字节侧依赖： 1、阅读灯+系统和设置相关的信号共9个，依赖P基线的实车。 2、道路导航相关的，拥堵、沿途服务区，相关的API上汽已提供 3、媒体播放2个，演员+导演名字，验证不通过； 4、智驾相关的，当前不具备验证条件； 无依赖进展： 1、道路导航相关的正在开发； 2、较多的异常信号，实车没有对应的信号block测试（47）；除去block通过率在：73%左右。
A40: 46206
A41: 模块\API（04.29变更前） | B41: 总api数 | C41: 本项目使用api数 | D41: 上汽已提供api数 | E41: 研发确认可用api数 | F41: 研发完成api数 | G41: 研发完成度 | H41: 测试覆盖api数 | I41: 测试执行完成度 | J41: 测试通过case数 | K41: case通过完成度 | L41: 备注
A42: 车控 | B42: 409 | C42: 399 | D42: 399 | E42: 389 | F42: 375 | G42: 0.93984962 | H42: 364 | I42: 0.9122807 | J42: 329 | K42: 0.8245614
A43: 系统设置 | B43: 126 | C43: 111 | D43: 106 | E43: 105 | F43: 101 | G43: 0.90990991 | H43: 79 | I43: 0.71171171 | J43: 68 | K43: 0.61261261
...

Sheet 车控车设进展汇总
A1: 模块\API（04.29变更前） | B1: 总api数 | C1: 本项目使用api数 | D1: 上汽已提供api数 | E1: 研发确认可用api数 | F1: 研发完成api数 | G1: 研发完成度 | H1: 测试覆盖api数 | I1: 测试执行完成度 | J1: 测试通过case数 | K1: case通过完成度 | L1: 备注 | M1: 上汽未提供 | N1: 研发确认中 | O1: 研发执行中 | P1: 测试执行中 | Q1: bug修复中
A2: 车控 | B2: =SUMIF('【对接进度说明】'!APNaN:APNaN,A2,'【对接进度说明】'!DNaN:DNaN) | C2: =SUMIF('【对接进度说明】'!APNaN:APNaN,A2,'【对接进度说明】'!ENaN:ENaN) | D2: =SUMIF('【对接进度说明】'!APNaN:APNaN,A2,'【对接进度说明】'!GNaN:GNaN) | E2: =SUMIF('【对接进度说明】'!APNaN:APNaN,A2,'【对接进度说明】'!INaN:INaN) | F2: =SUMIF('【对接进度说明】'!APNaN:APNaN,A2,'【对接进度说明】'!TNaN:TNaN) | G2: =F2/C2 | H2: 367 | I2: =H2/C2 | J2: =SUMIF('【对接进度说明】'!APNaN:APNaN,A2,'【对接进度说明】'!AINaN:AINaN) | K2: =J2/C2 | M2: =C2-D2 | N2: =D2-E2 | O2: =E2-F2 | P2: =F2-H2 | Q2: =H2-J2
A3: 系统设置 | B3: =SUMIF('【对接进度说明】'!APNaN:APNaN,A3,'【对接进度说明】'!DNaN:DNaN) | C3: =SUMIF('【对接进度说明】'!APNaN:APNaN,A3,'【对接进度说明】'!ENaN:ENaN) | D3: =SUMIF('【对接进度说明】'!APNaN:APNaN,A3,'【对接进度说明】'!GNaN:GNaN) | E3: =SUMIF('【对接进度说明】'!APNaN:APNaN,A3,'【对接进度说明】'!INaN:INaN) | F3: =SUMIF('【对接进度说明】'!APNaN:APNaN,A3,'【对接进度说明】'!TNaN:TNaN) | G3: =F3/C3 | H3: 79 | I3: =H3/C3 | J3: =SUMIF('【对接进度说明】'!APNaN:APNaN,A3,'【对接进度说明】'!AINaN:AINaN) | K3: =J3/C3 | M3: =C3-D3 | N3: =D3-E3 | O3: =E3-F3 | P3: =F3-H3 | Q3: =H3-J3
A4: 通讯 | B4: =SUMIF('【对接进度说明】'!APNaN:APNaN,A4,'【对接进度说明】'!DNaN:DNaN) | C4: =SUMIF('【对接进度说明】'!APNaN:APNaN,A4,'【对接进度说明】'!ENaN:ENaN) | D4: =SUMIF('【对接进度说明】'!APNaN:APNaN,A4,'【对接进度说明】'!GNaN:GNaN) | E4: =SUMIF('【对接进度说明】'!APNaN:APNaN,A4,'【对接进度说明】'!INaN:INaN) | F4: =SUMIF('【对接进度说明】'!APNaN:APNaN,A4,'【对接进度说明】'!TNaN:TNaN) | G4: =F4/C4 | H4: 24 | I4: =H4/C4 | J4: =SUMIF('【对接进度说明】'!APNaN:APNaN,A4,'【对接进度说明】'!AINaN:AINaN) | K4: =J4/C4 | M4: =C4-D4 | N4: =D4-E4 | O4: =E4-F4 | P4: =F4-H4 | Q4: =H4-J4
A5: 智能驾驶 | B5: =SUMIF('【对接进度说明】'!APNaN:APNaN,A5,'【对接进度说明】'!DNaN:DNaN) | C5: =SUMIF('【对接进度说明】'!APNaN:APNaN,A5,'【对接进度说明】'!ENaN:ENaN) | D5: =SUMIF('【对接进度说明】'!APNaN:APNaN,A5,'【对接进度说明】'!GNaN:GNaN) | E5: =SUMIF('【对接进度说明】'!APNaN:APNaN,A5,'【对接进度说明】'!INaN:INaN) | F5: =SUMIF('【对接进度说明】'!APNaN:APNaN,A5,'【对接进度说明】'!TNaN:TNaN) | G5: =F5/C5 | H5: 1 | I5: =H5/C5 | J5: =SUMIF('【对接进度说明】'!APNaN:APNaN,A5,'【对接进度说明】'!AINaN:AINaN) | K5: =J5/C5 | M5: =C5-D5 | N5: =D5-E5 | O5: =E5-F5 | P5: =F5-H5 | Q5: =H5-J5
A6: 多媒体 | B6: =SUMIF('【对接进度说明】'!APNaN:APNaN,A6,'【对接进度说明】'!DNaN:DNaN) | C6: =SUMIF('【对接进度说明】'!APNaN:APNaN,A6,'【对接进度说明】'!ENaN:ENaN) | D6: =SUMIF('【对接进度说明】'!APNaN:APNaN,A6,'【对接进度说明】'!GNaN:GNaN) | E6: =SUMIF('【对接进度说明】'!APNaN:APNaN,A6,'【对接进度说明】'!INaN:INaN) | F6: =SUMIF('【对接进度说明】'!APNaN:APNaN,A6,'【对接进度说明】'!TNaN:TNaN) | G6: =F6/C6 | H6: 75 | I6: =H6/C6 | J6: =SUMIF('【对接进度说明】'!APNaN:APNaN,A6,'【对接进度说明】'!AINaN:AINaN) | K6: =J6/C6 | M6: =C6-D6 | N6: =D6-E6 | O6: =E6-F6 | P6: =F6-H6 | Q6: =H6-J6
A7: 地图导航 | B7: 69 | C7: 69 | D7: 69 | E7: 59 | F7: 59 | G7: =F7/C7 | H7: 61 | I7: =H7/C7 | J7: 37 | K7: =J7/C7 | L7: 不含AInavi | M7: =C7-D7 | N7: =D7-E7 | O7: =E7-F7 | P7: =F7-H7 | Q7: =H7-J7
A8: 手车互联 | B8: =SUMIF('【对接进度说明】'!APNaN:APNaN,A8,'【对接进度说明】'!DNaN:DNaN) | C8: =SUMIF('【对接进度说明】'!APNaN:APNaN,A8,'【对接进度说明】'!ENaN:ENaN) | D8: =SUMIF('【对接进度说明】'!APNaN:APNaN,A8,'【对接进度说明】'!GNaN:GNaN) | E8: =SUMIF('【对接进度说明】'!APNaN:APNaN,A8,'【对接进度说明】'!INaN:INaN) | F8: =SUMIF('【对接进度说明】'!APNaN:APNaN,A8,'【对接进度说明】'!TNaN:TNaN) | G8: =F8/C8 | H8: 0 | I8: =H8/C8 | J8: =SUMIF('【对接进度说明】'!APNaN:APNaN,A8,'【对接进度说明】'!AINaN:AINaN) | K8: =J8/C8 | M8: =C8-D8 | N8: =D8-E8 | O8: =E8-F8 | P8: =F8-H8 | Q8: =H8-J8
A9: 通用 | B9: =SUMIF('【对接进度说明】'!APNaN:APNaN,A9,'【对接进度说明】'!DNaN:DNaN) | C9: =SUMIF('【对接进度说明】'!APNaN:APNaN,A9,'【对接进度说明】'!ENaN:ENaN) | D9: =SUMIF('【对接进度说明】'!APNaN:APNaN,A9,'【对接进度说明】'!GNaN:GNaN) | E9: =SUMIF('【对接进度说明】'!APNaN:APNaN,A9,'【对接进度说明】'!INaN:INaN) | F9: =SUMIF('【对接进度说明】'!APNaN:APNaN,A9,'【对接进度说明】'!TNaN:TNaN) | G9: =F9/C9 | H9: 3 | I9: =H9/C9 | J9: =SUMIF('【对接进度说明】'!APNaN:APNaN,A9,'【对接进度说明】'!AINaN:AINaN) | K9: =J9/C9 | M9: =C9-D9 | N9: =D9-E9 | O9: =E9-F9 | P9: =F9-H9 | Q9: =H9-J9
B10: =SUM(B2:B9) | C10: =SUM(C2:C9) | D10: =SUM(D2:D9) | E10: =SUM(E2:E9) | F10: =SUM(F2:F9) | G10: =F10/C10 | H10: =SUM(H2:H9) | I10: =H10/C10 | J10: =SUM(J2:J9) | K10: =J10/C10
A11: 端状态信号 | B11: =IMPORTRANGE("https://bytedance.larkoffice.com/wiki/UcRRwKhTEi6by2ks5vNcjGdtnb9?from=from_copylink", "端状态进展汇总!B9") | C11: =IMPORTRANGE("https://bytedance.larkoffice.com/wiki/UcRRwKhTEi6by2ks5vNcjGdtnb9?from=from_copylink", "端状态进展汇总!C9") | D11: =IMPORTRANGE("https://bytedance.larkoffice.com/wiki/UcRRwKhTEi6by2ks5vNcjGdtnb9?from=from_copylink", "端状态进展汇总!D9") | E11: =IMPORTRANGE("https://bytedance.larkoffice.com/wiki/UcRRwKhTEi6by2ks5vNcjGdtnb9?from=from_copylink", "端状态进展汇总!E9") | F11: =IMPORTRANGE("https://bytedance.larkoffice.com/wiki/UcRRwKhTEi6by2ks5vNcjGdtnb9?from=from_copylink", "端状态进展汇总!G9") | G11: =F11/C11 | H11: =IMPORTRANGE("https://bytedance.larkoffice.com/wiki/UcRRwKhTEi6by2ks5vNcjGdtnb9?from=from_copylink", "端状态进展汇总!I9") | I11: =H11/C11 | J11: =IMPORTRANGE("https://bytedance.larkoffice.com/wiki/UcRRwKhTEi6by2ks5vNcjGdtnb9?from=from_copylink", "端状态进展汇总!K9") | K11: =IMPORTRANGE("https://bytedance.larkoffice.com/wiki/UcRRwKhTEi6by2ks5vNcjGdtnb9?from=from_copylink", "端状态进展汇总!M9") | L11: =IMPORTRANGE("https://bytedance.larkoffice.com/wiki/UcRRwKhTEi6by2ks5vNcjGdtnb9?from=from_copylink", "端状态进展汇总!N9")

Sheet 【对接进度说明】
A1: 模块 | B1: 功能名称 | C1: 状态@方令平 | D1: API总数 @方令平 | E1: 本车使用API数 | F1: [API]支持比例@周怀君 | G1: [API]已支持@周怀君 | H1: [API]待支持@周怀君 | I1: 字节识别接口可用数量@汪帅 | J1: 上汽API可用率@汪帅 | K1: [API]已提供的API状态备注@汪帅 详见各sheet页D列 | L1: 负责人 | M1: 【API】解决计划 | N1: [API]解决计划详情 | O1: [实车]支持状态 按HMI点检@方令平 （百分比） | P1: [实车]支持状态 （已支持） | Q1: [实车]支持状态 （待支持） | R1: [实车]支持状态备注 | S1: [实车]支持计划 | T1: 已对接API数量@汪帅 | U1: 字节对接进度@汪帅 （按功能总条数） （百分比） | V1: 字节对接进度 （按总数量） （待完成） | W1: 优先级 | X1: PRD进展 | Y1: 完成计划 | Z1: 主开发 （service逻辑+上汽原子能力） | AA1: 备开发 （单纯的其他项目原子能力） | AB1: 测试进度（已测试case数/测试case总数） @赵晓健 （百分比） | AC1: 测试进度（按[实车】支持状态） （已测试） | AD1: 测试进度（按总数量） （待测试） | AE1: 测试通过率（测试通过case数/已测试case数） （百分比） | AF1: 测试通过case数 | AG1: 已测试case数 | AH1: 测试case总数 | AI1: 已测试通过case数 （已通过） | AJ1: 尚未通过case（按总数） | AK1: 尚未通过case （按已测试） | AL1: 测试负责方 前提：双方拉齐测试用例 | AM1: Bug链接 | AP1: 模块 | AQ1: 总case数-api数 | AR1: 需确认项 | AU1: 双方联合走查计划 | AV1: 顺序
A2: 车控 | B2: 车窗 | C2: 已完成 | D2: 26 | E2: 26 | F2: =G2/E2 | G2: 26 | H2: =E2-G2 | I2: 26 | J2: =I2/E2 | K2: 打开/关闭车窗API（涉及百分比）待上汽排查定位。 4.27 等待fc,逻辑完成待上车模拟自测 5.06 雨天自动锁窗广播自测成功；实车FC没有下发；没有豆包话术编号 0515.等待产品添加车窗锁端状态 0601 “后排车窗锁”端状态的询问有问题，已转服务端，待服务端更新剩余bug在服务端余昭志，余明明在推 0603 余明明：需要服务端增加对应的端状态，已联系吴仁杰，暂未反馈预计完成时间 0608 余明明在内部群追吴仁杰，等反馈 0703/0710 3个❌ | N2: 计划软件3.0.9版本在03.13释放。 @刘敬思待刷新后自测验证。 | O2: =P2/E2 | P2: 26 | T2: 26 | U2: =T2/E2 | V2: =E2-T2 | W2: P0 | X2: ✅ | Y2: 01.30 4.30 广播自测成功；等待豆包话术编号 | Z2: @余明明 | AA2: @谢一鸣 | AB2: =AG2/AH2 | AC2: =AG2 | AD2: =E2-AC2 | AE2: =AF2/AG2 | AF2: =COUNTIFS('车控'!Q2:Q27,"✅") | AG2: =COUNTIFS('车控'!Q2:Q27,"✅")+COUNTIFS('车控'!Q2:Q27,"❌")+COUNTIFS('车控'!Q2:Q27,"Block") | AH2: 26 | AI2: =AF2 | AJ2: =AH2-AF2 | AK2: =AG2-AF2 | AL2: 字节-刘晓帝 FAIL | AM2: https://bytedance.larkoffice.com/record/Vb0Gr6YEsepy2KcSTSLc75qLnEn https://bytedance.larkoffice.com/record/MN77rcf6gefUwJctnRccuF3Sn5T https://bytedance.larkoffice.com/record/AzY6rotxkePY81crMwrcvcyvnbh https://bytedance.larkoffice.com/record/VB44rLlpKeIb2Pcivepc41KynKb https://bytedance.larkoffice.com/record/FMNkrsBeYegmewctbwccoPlin6g https://bytedance.larkoffice.com/record/KXhfr89CLeRIfvcnTpxcRWS8n7e https://bytedance.larkoffice.com/record/NE0crAOPheNvrsc2OFacZ5hOnoh https://bytedance.larkoffice.com/record/UqyPriTOceQPk2cK286cUiD1niC | AN2: 雨天自动关窗的2个控制无效 | AP2: 车控 | AQ2: =AH2-E2 | AU2: 周二 | AV2: 7
B3: 空调 | C3: 【火山】待问题修复 | D3: 63 | E3: 63 | F3: =G3/E3 | G3: 63 | H3: 0 | I3: 63 | J3: =I3/E3 | K3: ①查询车内空气质量，不支持； ②查询车外温度，一直是-40°； ③控制空调经济模式，不支持； ④控制智能空调，不支持； ⑤控制空气自干燥除味功能，不支持； ⑥控制后排屏空调锁定，不支持； ⑦控制智能除雾，不支持。 04.02： 实车空调支持最大值HI最小值LOW，目前温度调节数值范围是16～30，HI和LOW是否有单独的接口 @guixiang ZoneAPI不支持的，详见车控sheet页。 04.15：@左晨&@赵明珠，对齐标灰或删除线的控制内容的支持方式。 04.20：不支持的部分tts兜底 0528 怀君给了最下面6个（打开 / 关闭智能空调 、打开 / 关闭智能空调、打开/关闭新风、打开/关闭智能送风、打开/关闭智能温区、打开/关闭智能新风）待开发确认api是否可用 @赵明珠：接口已提供，实车目前不支持测试。/ @方令平 解决实车阻碍 0602 令平反馈找上汽陈科解决，待整理所有实车不支持问题再飞书群找陈科 0603 赵明珠：怀君说p基线才有（p基线预计本周内上），开发本周完成 0622 真车排队 0622:实车未找到新风送风功能，HML上按钮回弹 ，智能新风、温区按钮回弹 0625:按钮回弹问题已反馈桂祥，新风、送风功能已找到 0629、0701 6个待明珠验证。 0703 6个待明珠验证。6个0625❌ 0706:新风、智能送风、智能温区、智能新风、智能空调。FC下发错误已转给云端解决 0708 fc下发错误已提meego bug给泽民/泽民反馈预计今天动态示例解决，已通知明珠0709发版后验一下 0709: FC自测验证通过，智能送风HMI按钮回弹：http://jira.z-onesoftware.com:8080/browse/DNA-3017 | N3: 1.未收到产品需求； 2.API就绪，车辆传感器待配置； 3.未收到产品需求； 4.未收到产品需求； 5.PPV版本已支持，待提供API； 6.未收到产品需求； 7.PPV版本已支持，待提供API； 补充API见最后一列。 剩余是AI智能空调，P阶段新增需求，排期P基线 5/15:P基线SOA信号延期释放，推迟到5/21提供给字节 0527: 0526提供的api，预计开发完成；@赵明珠 | O3: =P3/E3 | P3: 63 | Q3: =E3-P3 | T3: 63 | U3: =T3/E3 | V3: =E3-T3 | W3: P0 | X3: ✅ | Y3: 06.05 | Z3: @赵明珠 | AA3: @尹泽陆 @康楷朋 | AB3: =AG3/AH3 | AC3: =AG3 | AD3: =E3-AC3 | AE3: =AF3/AG3 | AF3: =COUNTIFS('车控'!Q28:Q92,"✅") | AG3: =COUNTIFS('车控'!Q28:Q92,"✅")+COUNTIFS('车控'!Q28:Q92,"❌")+COUNTIFS('车控'!Q28:Q92,"Block") | AH3: 63 | AI3: =AF3 | AJ3: =AH3-AF3 | AK3: =AG3-AF3 | AL3: 字节-郑永超 FAIL | AM3: https://bytedance.larkoffice.com/record/KnFHrPKMpeoDRAcRH8hcBqxmn1d https://bytedance.larkoffice.com/record/Qh7hrPWWHeDAnycQXOIcrLO1nDe https://bytedance.larkoffice.com/record/OM5UrIwISeUlOpcv9xyceywKnWg https://bytedance.larkoffice.com/record/Uo2yrneFcel0qIcSomxceYHPnQe | AP3: 车控 | AQ3: =AH3-E3 | AR3: @赵明珠 上汽新接口确认结果，确认协议满足哪几个api、预计开发接api完成时间？以及bug修复进度？- | AS3: 接口已提供，实车目前不支持测试 | AU3: 周二 | AV3: 2
B4: 电动出风口 | C4: 已完成 | D4: 17 | E4: 17 | F4: =G4/E4 | G4: 17 | H4: =E4-G4 | I4: 17 | J4: =I4/E4 | K4: 车控SDK API就绪并已完成对接。 04.15：@左晨&@赵明珠，对齐标灰或删除线的控制内容的支持方式。 04.20：电动出风口今天收尾-> 已处理 0622 研发名下无bug 0624 1个api（关闭前排出风口）测试❌ 0703/0710 1个❌ | O4: =P4/E4 | P4: 17 | Q4: =E4-P4 | T4: 17 | U4: =T4/E4 | V4: =E4-T4 | W4: P0 | X4: ✅ | Y4: 01.30 | Z4: @赵明珠 | AA4: @康楷朋 | AB4: =AG4/AH4 | AC4: =AG4 | AD4: =E4-AC4 | AE4: =AF4/AG4 | AF4: =COUNTIFS('车控'!Q93:Q109,"✅") | AG4: =COUNTIFS('车控'!Q93:Q109,"✅")+COUNTIFS('车控'!Q93:Q109,"❌")+COUNTIFS('车控'!Q93:Q109,"Block") | AH4: 17 | AI4: =AF4 | AJ4: =AH4-AF4 | AK4: =AG4-AF4 | AL4: 字节-刘晓帝 FAIL | AM4: https://bytedance.larkoffice.com/record/VsbRraKTyegy8YcLdjZcp1abnob https://bytedance.larkoffice.com/record/VEiDr6L8jezHKJcZ5TmceZvXnSc https://bytedance.larkoffice.com/record/Ij7zr88xreqmYOcIkTqc0sm9nph https://bytedance.larkoffice.com/record/UwCurdeOLeChIHcMZuqczaOrnmf https://bytedance.larkoffice.com/record/VXwrr4JmWehHtJcf0tNczlcynne https://bytedance.larkoffice.com/record/DVFSrabxDeQWbwcoq2rcaGchnfh https://bytedance.larkoffice.com/record/Clx5r1gvaeQpddcPCoVc7zq1nKb https://bytedance.larkoffice.com/record/CaiNreLVueitpDc6sjGcM4lknkc | AP4: 车控 | AQ4: =AH4-E4 | AR4: @刘晓帝本车无此功能和本车有此功能但走兜底，是否需要测？进度表里总case是13个，模块表里4个删除线api都划掉了，这4个是否已测且通过？-已完成
B5: 座椅 | C5: 【火山】待问题修复 | D5: 39 | E5: 39 | F5: =G5/E5 | G5: 39 | H5: =E5-G5 | I5: 39 | J5: =I5/E5 | K5: 1. 打开/关闭座椅页面接口仍然缺失； 2.座椅/座垫/腰托/腿托的位置调节，参数不太明确，参数3的SeatConstants.SeatAdjustStatus没有太看明白，如果我想要调节到30%这种如何转换呢，就是没有看到具体的位置的值或者档位。 /** * 座椅位置设置(百分比设置) * PermissionRequest(permissions = { zone.permission.vehicle.SEAT_SET }) * @param seatType 设置值 {@link SeatType} * @param direction 设置值 {@link SeatDirection} * @param position 设置值 0～255 * @return resultCode 返回结果码 {@link ResultCode} */ int setSeatAdjustmentPosition(@SeatType int seatType, @SeatDirection int direction, int position); SEAT_ADJUSTMENT_POSITION FLAG 3.SDK内缺方向盘加热控制的API 座椅腰托调节ZoneAPI不支持。 04.15：@左晨产品确认腰托支持内容。-》答复：腰托不支持极限值调节，可支持上/下/前/后调节。 04.20：确定最终腰托量产的一个方案 4.22 上汽~ 腰托极值开发完毕，返回正常实际没执行，抓了日志待上汽排查； 字节~腿拖FC云端没下发，请客户端和服务端排查 05.19 请上汽明确腰托实际未执行的bug状态 负责人：上汽邵凯 上汽bug单dna-674 0601 邵凯反馈：整车基线刷成p基线的就可以正常了 0622 真车排队 0624 1个api（腰托）开发“空”，5个api测试❌ 0703 7个0625❌，1个0703刚提测❌ 0706 7个0625❌ 0710 1个❌ | N5: 1.已提供打开指令。private val VOICE_CLOSE_SEAT_SCENE = "com.zone.hmi.hvac.service.voice_close_seat_scene" 2.PP版本提供具体调节值的API： 需要在PP基线4.0.3版本进行验证；接口sdk和服务已提供（车控的） 3.车控表格中已提供API说明，但当前版本SDK没有，@陈果果需找杨方舟更新。 03.06： D列有未识别API状态的内容，请@周怀君协调确认更新； 03.10：语音模块负责 | O5: =P5/E5 | P5: 39 | Q5: =E5-P5 | R5: 实车不支持座椅电控 | S5: 4月初，更新IS4PR PPV1车辆。 | T5: 39 | U5: =T5/E5 | V5: =E5-T5 | W5: P0 | X5: ✅ | Y5: 待问题修复 | Z5: @陈果果 | AA5: @杨忠谕 | AB5: =AG5/AH5 | AC5: =AG5 | AD5: =E5-AC5 | AE5: =AF5/AG5 | AF5: =COUNTIFS('车控'!Q110:Q148,"✅") | AG5: =COUNTIFS('车控'!Q110:Q148,"✅")+COUNTIFS('车控'!Q110:Q148,"❌")+COUNTIFS('车控'!Q110:Q148,"Block") | AH5: 39 | AI5: =AF5 | AJ5: =AH5-AF5 | AK5: =AG5-AF5 | AL5: 上汽 FAIL 字节-王东旭 FAIL | AM5: https://bytedance.larkoffice.com/record/KkR7rEx1ceYRFscJAcLcI6UqnNe https://bytedance.larkoffice.com/record/JxKbrjqiLeeTzlcZj5Xcu0hRnCs https://bytedance.larkoffice.com/record/FUSirxe3Bey3pVcsQPycCAvmnfg https://bytedance.larkoffice.com/record/FdIgrftsUeqKqNc2v1UcCDoWnFb https://bytedance.larkoffice.com/record/LVDBr985Ce8SlIcPUozcUVqTnkh https://bytedance.larkoffice.com/record/H0SKrLWNee8Qrzc48ILcPwAknYf https://bytedance.larkoffice.com/record/QIt4rQ3vBeofgPcpmUGc8dyOngb https://bytedance.larkoffice.com/record/OWyHrDOWLetv8jcV8u8c4IKfnae https://bytedance.larkoffice.com/record/Bc0orEI24efJtgcuUvgcHh6wnYb https://bytedance.larkoffice.com/record/WHmar4YrIe51dMco5l6ctZapnuh | AP5: 车控 | AQ5: =AH5-E5 | AR5: @陈果果 模块表研发进展39✅，进度表已接37，是否差模块表137和139两行？-只有一个137，腰托接口还有问题，之前填写进度表已接入应该是38 @陈果果@王东旭 除了腰托两条，其他测试进展❌的 bug修复进度？-挂头上的bug都已解决，不挂头上的依赖三方 | AU5: 周二 | AV5: 1
B6: 外后视镜 | C6: 【火山】待问题修复 | D6: 12 | E6: 12 | F6: =G6/E6 | G6: 12 | H6: =E6-G6 | I6: 12 | J6: =I6/E6 | K6: ①语音打开后视镜设置页面，不支持； ②语音控制外后视镜方向调节，不支持； ③语音控制外后视镜倒车下倾设置，不支持； ④语音控制外后视镜自动展开折叠设置，不支持。 8、倒车后视镜自动下倾，单侧都可以打开和关闭，但是同时打开和关闭双侧api接口返回状态成功，但是不执行 0703/0710 2个❌ 0721 一鸣反馈有两个内部fc的票 | L6: @王泽民 @宋丛丛 @谢一鸣 | M6: https://meego.larkoffice.com/telematics/issue/detail/7357105095?from=from_parent_docs&tabKey=detail#detail https://meego.larkoffice.com/telematics/issue/detail/7356996132?from=from_parent_docs&tabKey=detail#detail | N6: 8.上汽侧Bug票跟进。计划软件3.0.9版本释放。 03.10： @周怀君待更新ZXD 3.0.9版本早03.15释放。。 3.17 都已解决 | O6: =P6/E6 | P6: 12 | Q6: =E6-P6 | T6: 12 | U6: =T6/E6 | V6: =E6-T6 | W6: P0 | X6: ✅ | Y6: 02.28 | Z6: @谢一鸣 | AA6: @樊晓天 | AB6: =AG6/AH6 | AC6: =AG6 | AD6: =E6-AC6 | AE6: =AF6/AG6 | AF6: =COUNTIFS('车控'!Q149:Q160,"✅") | AG6: =COUNTIFS('车控'!Q149:Q160,"✅")+COUNTIFS('车控'!Q149:Q160,"❌")+COUNTIFS('车控'!Q149:Q160,"Block") | AH6: 12 | AI6: =AF6 | AJ6: =AH6-AF6 | AK6: =AG6-AF6 | AL6: 字节-刘晓帝 PASS | AP6: 车控 | AQ6: =AH6-E6
B7: 尾门 | C7: 【火山】产品功能待澄清 | D7: 13 | E7: 10 | F7: =G7/E7 | G7: 10 | H7: =E7-G7 | I7: 10 | J7: =I7/E7 | K7: 4、设置后备箱预设位置，错误码：3010015，权限问题： reqType: TAILGATE_POSITION ，permission:zone.permission.vehicle.DOOR_WINDOW_LOCK_SETnot Granted 。SUV 不存在该问题 5、打开后备箱，错误码：3010015，权限问题： reqType: TAILGATE_STATUS permission:zone.permission.vehicle.DOOR_WINDOW_LOCK_SETnot Granted 。SUV可以正常打开。 ~~~4&5，上汽提供降低权限的SDK用于集成，待提供给一鸣。Done。 6、后备箱实际位置和api获取到的位置不符合，实际位置一直显示未0 ,SUV 同样存在该问题获取到的位置不对 ~~~实车无此接口，车模有此接口。待评估适用性。 7、SUV 后备箱状态不对，实际是打开的，查询却是关闭的 9、后备箱预设值高度100，实际开启高度很低 （后备箱开启的角度和预设不一致） 04.20：与左晨沟通暂停来不及问题如何处理 =》产品回复先接口接入，实际测试再沟通 0528 @谢一鸣 3个api 卡实车验证 接口是否验证通过？ 卡实车 / @王东旭：实车不支持暂停和开合度调整block 6个api 163-168 /@方令平推进实车问题/0608 与怀君确认当前实车是否支持，等反馈 0610 4个api（暂停电尾门、暂停后备箱、继续打开、暂停关闭），一鸣反馈在实车验证时分析发现在尾门打开过程中发出暂停的语音指令，等fc返回时，尾门已全部打开/关闭，需产品确认后续如何解决/左晨反馈fc下发时效没那么快，无法在尾门执行完打开/关闭之前返回，目前时效只能这样了，已反馈给董晓颖 2个api（把电动尾门开合度调到 50%、电尾门开度设为 80%），一鸣反馈之前左晨对上汽接口理解有歧义，左晨更新逻辑后需要更改fc，已提工单给产品，工单recvlzKIaNyYlp/0617 婉婷已确认会加，预计1.8能上/0622 1.8已评审，待服务端、算法、测试排期/0623 预计0630前能上线 3个api（开启前备箱、关闭电动前备箱/关前备箱、暂停前备箱）实车没有前备箱 | L7: @左晨 | N7: 6&7&9，上汽建票SP部门支持。@周怀君待反馈时间。 03.06： *** 尾门相关API对接都依赖状态获取 *** 03.12： 上汽侧协调自学习后验证。 3.17： 怀君在16号晚上反馈可以验证，开发实测还是不行（自学习后状态未保存）。 3.18： 自学习后上大电失忆，fix在03.23。短期保证一次上下电稳定，提前学习。@谢一鸣明天验证，@邴岱一配合自学习状态就绪。 04.23： 169、170、171行接口已提供，但该功能依赖EV车型，待EV实车进行验证 | O7: =P7/E7 | P7: 10 | Q7: =E7-P7 | R7: 04.20 PPV1实车PHEV不支持前备箱。 | S7: EV车接口已支持，待配置实车后才能验证。 | T7: 6 | U7: =T7/E7 | V7: =E7-T7 | W7: P0 | X7: ✅ | Y7: 02.28：后备箱 04.28：前备箱 | Z7: @谢一鸣 | AA7: @樊晓天 | AB7: =AG7/AH7 | AC7: =AG7 | AD7: =E7-AC7 | AE7: =AF7/AG7 | AF7: =COUNTIFS('车控'!Q161:Q173,"✅") | AG7: =COUNTIFS('车控'!Q161:Q173,"✅")+COUNTIFS('车控'!Q161:Q173,"❌")+COUNTIFS('车控'!Q161:Q173,"Block") | AH7: 10 | AI7: =AF7 | AJ7: =AH7-AF7 | AK7: =AG7-AF7 | AL7: 字节-郑永超 FAIL（FAIL项目主要是实车调节高度目前因为开关太快导致无法验证） | AP7: 车控 | AQ7: =AH7-E7 | AR7: @王东旭 模块表里6个api测试block（进度表里显示5个case未通过，更新数据），原因？解决人是否已对接？何时解决？进度表里的总caes是否应改为13（目前双方确定了是13个api）？-实车不支持暂停和开合度调整
B8: 雨刮 | C8: 已完成 | D8: 8 | E8: 8 | F8: =G8/E8 | G8: 8 | H8: =E8-G8 | I8: 8 | J8: =I8/E8 | K8: ①雨刮维修模式开关（雨刷档位状态<上汽内部没接收此需求>、车档位状态、错误码不正确）； ②雨刮其他控制接口，不支持。 1、车档位：P档值为2，返回值为1与汽车实际档位不符合 2、雨刷档位（getFrtWiperMdSts）：OFF档位为：5，返回的值为：0，不管切换什么档位都为0。SUV问题同样存在 3、设置雨刷维修模式状态（setWipeRepairStatus）：返回错误码：3010015 , SUV 状态码正常但是没有执行 ~~~上汽反馈更新PRD，暂未更新反馈。 04.14：实车不支持雨刮 meego: https://meego.larkoffice.com/telematics/issue/detail/7088293062 04.20：处理雨刮bug单 =》bug单已处理 0527:待测试确认是否完成测试@赵晓健:0528完成 | N8: 1.已解决； 2.更新PRD； 3.在2的前提下再支持。 03.10：上汽@陈振英反馈本周更新PRD 03.13：上汽侧提供部分更新PRD。①依赖上汽PO梳理拆解变更项。②剩余待更新PRD预计03.18提供。整体更新PRD的澄清，预计周三/周四沟通。 03.19：双方PO澄清变更内容，PRD有更新，详见Sheet页。 | O8: =P8/E8 | P8: 8 | Q8: =E8-P8 | R8: 04.15： 前雨刮维修模式，HMI回弹，实际控制不生效。 04.21：实车验证fail，计划集成4.0.7软件版本验证应用层问题。 | T8: 8 | U8: =T8/E8 | V8: =E8-T8 | W8: P0 | X8: ✅ | Y8: 04.21 | Z8: @谢一鸣 | AA8: @余明明 | AB8: =AG8/AH8 | AC8: =AG8 | AD8: =E8-AC8 | AE8: =AF8/AG8 | AF8: =COUNTIFS('车控'!Q174:Q181,"✅") | AG8: =COUNTIFS('车控'!Q174:Q181,"✅")+COUNTIFS('车控'!Q174:Q181,"❌")+COUNTIFS('车控'!Q174:Q181,"Block") | AH8: 8 | AI8: =AF8 | AJ8: =AH8-AF8 | AK8: =AG8-AF8 | AL8: 上汽 PASS 字节-王东旭 FAIL | AM8: https://bytedance.larkoffice.com/record/Ibplr5HRueqYhncN6McceTUMnKe https://bytedance.larkoffice.com/record/KzAOrafdOeCnHacfiK6ckJ8unyf | AP8: 车控 | AQ8: =AH8-E8 | AR8: @王东旭 进度表100%通过率，模块表测试进展列数据更新一下-已完成
B9: 遮阳帘 | C9: 【火山】产品功能待澄清 | D9: 17 | E9: 17 | F9: =G9/E9 | G9: 17 | H9: =E9-G9 | I9: 17 | J9: =I9/E9 | K9: 进行中 3.31 步进调节、百分比调节接口暂不具备4.2换新接口自测中 4.3fc无下发,昭志排查 4.3UI及硬件都无反应，log已发，上汽说等新车来了再试，目前的车有问题 4.8后车不支持，前车支持 4.16： 遮阳帘前后排语音控制接口返回失败,上汽已起票。 04.20： 全部都阻塞在上汽接口处 04.21: 253实车遮阳帘时好时坏，上汽已经起票；254实车RZCU更新软件---待反馈时间@董晓颖 04:28 设置开合度api可用，获取开合度api始终是 1 。 05.19 待明确254实车RZCU软件更新时间； 待明确开合度状态值bug。 上汽负责人：杨方舟 05.21 275实车开合度状态值Bug，杨方舟明确要底软去排查 锁车自动关闭遮阳帘的api可以，FC暂时不下发 05.26 同21号问题依旧（问题影响的api是否是模块表里193、194、195三个api） 0602 遮阳帘有误差，最后会导致关闭不起来。 怀君转给晓颖跟进，等反馈 0608 @余明明 有问题的fc都有bug单 0610 产品新识别出一个api需要接，fc侧放在v1.5中上，扽v1.5上线后开发 0613 明明：FC下发正常，但接口不执行 0615 需与明明确认bug单recvlWElvhvatJ与剩下没好的api遮阳帘暂停没关系，具体情况如何（没有bug单） 0615 暂停功能自测ok提测 0622 研发名下无bug 0703 1个测试block，机械执行比语音快，暂停功能实现不来，与左晨确认是否与尾门同样问题的处理方法一致，待反馈/与尾门一样 | L9: @左晨 | N9: 遮阳帘初始化问题，已修复，待释放版本验证 04.24：验证通过，待字节确认 | O9: =P9/E9 | P9: 17 | Q9: =E9-P9 | R9: 实车无遮阳帘 04.08：PPV1实车暂不支持遮阳帘电动控制。不支持自测。 04.14：HMI支持遮阳帘控制，不支持暂停、不支持完全打开。 04.20：实车遮阳帘初始化错误，导致功能block，DNA-335票处理中。---待反馈排期@周怀君---计划集成4.0.7软件版本验证（测试：04.22-254刷了407没标定无法验证） | S9: 46134 | T9: 17 | U9: =T9/E9 | V9: =E9-T9 | W9: P1 | X9: ✅ | Y9: 04.28 | Z9: @余明明 | AA9: @杨忠谕 | AB9: =AG9/AH9 | AC9: =AG9 | AD9: =E9-AC9 | AE9: =AF9/AG9 | AF9: =COUNTIFS('车控'!Q182:Q198,"✅") | AG9: =COUNTIFS('车控'!Q182:Q198,"✅")+COUNTIFS('车控'!Q182:Q198,"❌")+COUNTIFS('车控'!Q182:Q198,"Block") | AH9: 16 | AI9: =AF9 | AJ9: =AH9-AF9 | AK9: =AG9-AF9 | AL9: 字节-刘晓帝 | AM9: https://bytedance.larkoffice.com/record/GdW4rvUqjeG1AdcYoUtcdpYwnph https://bytedance.larkoffice.com/record/ON1prVSuKeU1TYcsLHpcu3Txnlg | AP9: 车控 | AQ9: =AH9-E9 | AR9: @王东旭 当前遇到的问题影响的api是否是模块表里193、194、195三个？如果不是，请更新数据-是
B10: 门锁 | C10: 已完成 | D10: 5 | E10: 5 | F10: =G10/E10 | G10: 3 | H10: =E10-G10 | I10: 5 | J10: =I10/E10 | K10: sdk调用时好时不好bug 3.191门锁： 1.1fc下发有时正确有时相反问题已反馈需求 待解决 1.2门锁调用接口参数按给的参数定义写的，还是有时正确有时相反问题需要查看log排查一下 3.20 1.1fc下发有时正确有时相反问题已反馈 左晨说测试提测给算法 1.2门锁调用接口参数按给的参数定义写的，还是有时正确有时相反问题需上汽查看log排查一下 fc下发一会正常一会相反，需要算法测修改4.13fc下发问题，UI无响应硬件无响应 4.14UI无响应无法点击4.16开锁UI无响应 04.16: @赵明珠车门状态返回信号存在问题，位置数值对不上，确认是否有开度值，目前只有开关 => 04.20：待抓日志上汽排查---04.21 按照门的透传值来开发 上汽吴佳军。 04.16: @赵明珠实车是否支持儿童锁 => 04.20：字节需要端状态上汽接口不支持，这个上汽不支持 04.16：@刘敬思语音控制开锁异常，待上汽反馈。 04.20：@刘敬思反馈预解决日期4.21待上汽解决bug 04.21：语音SDK调用“中控锁解锁”，待上汽起票推进解决。@周怀君4.22门锁已修复 04.24：剩余2条儿童锁，该车型不支持 0507:字节：上锁可以，解锁云端拒识 05.19：@刘敬思自测下儿童锁兜底话术 05.26：FC没下发导致端侧兜底话术没执行，确认云端话术是否符合预期。待关闭。 5.27: 测试复测验证；@赵晓健@刘晓帝 0615、0622 开发都提测了并且开发名下没有bug，3个测试❌需要与测试同事王东旭确认bug | N10: 待上汽排查 3.191门锁： 1.1fc下发有时正确有时相反问题已反馈需求 待解决 1.2门锁调用接口参数按您给的参数定义写的，还是有时正确有时相反问题需要查看log排查一下 | O10: =P10/E10 | P10: 5 | Q10: =E10-P10 | R10: 04.09：HMI设置回弹。 04.14：中控锁解锁/闭锁，HMI页面不可点击。 04:16：前置需要关闭所有车门，HMI也点击可以 | T10: 5 | U10: =T10/E10 | V10: =E10-T10 | W10: P0 | X10: ✅ | Y10: 4.22 | Z10: @高宇新 | AA10: @余明明 | AB10: =AG10/AH10 | AC10: =AG10 | AD10: =E10-AC10 | AE10: =AF10/AG10 | AF10: =COUNTIFS('车控'!Q204:Q208,"✅") | AG10: =COUNTIFS('车控'!Q204:Q208,"✅")+COUNTIFS('车控'!Q204:Q208,"❌")+COUNTIFS('车控'!Q204:Q208,"Block") | AH10: 5 | AI10: =AF10 | AJ10: =AH10-AF10 | AK10: =AG10-AF10 | AL10: 字节-刘晓帝 FAIL | AM10: https://bytedance.larkoffice.com/record/ErB9rNnnIehfw2cOIOmcx3xSnMg https://bytedance.larkoffice.com/record/RxrZrOYkhecH9EcZ7XycWzhSnGg https://bytedance.larkoffice.com/record/Iyywrgsh2eQA08cSItScxKQCnzh | AP10: 车控 | AQ10: =AH10-E10 | AR10: @王东旭进度表总case10，是否覆盖儿童锁2api？整个门锁的测试进展更新模块表（目前是3❌2block）-已完成
B11: 充电管理 | C11: 已完成 | D11: 4 | E11: 4 | F11: =G11/E11 | G11: 1 | H11: =E11-G11 | I11: 1 | J11: =I11/E11 | K11: 04.09、4.10：语音控制充电门，接口控制失效。上汽tanzhongzhou反馈接口不支持。 04.20:@陈果果与产品和上汽沟通最终充电小门的状态 04.23：不支持的功能，TTS兜底回复。已开发完毕，待自测 0528:确认最终只有一个API，其它不支持。 走兜底的话，在模块表里的研发进展里如何标记，需要大家统一 0615、0622开发已提测且名下无bug，需要与测试郑永超确认bug | N11: 该车型不支持 充电小门2条，需求确认不支持语音控制 加油小门1条，需求确认不支持语音控制关闭 待上汽产品更新PRD输入。 | O11: =P11/E11 | P11: 1 | Q11: =E11-P11 | R11: 04.15：实车不支持充电口电控打开/关闭。 | S11: 该车型不支持，需产品更新PRD | T11: 4 | U11: =T11/E11 | V11: 0 | W11: P1 | X11: ✅ | Y11: 4.21 当前开发完毕待验证了 | Z11: @陈果果 | AA11: @尹泽陆 | AB11: =AG11/AH11 | AC11: =AG11 | AD11: =E11-AC11 | AE11: =AF11/AG11 | AF11: =COUNTIFS('车控'!Q209:Q212,"✅") | AG11: =COUNTIFS('车控'!Q209:Q212,"✅")+COUNTIFS('车控'!Q209:Q212,"❌")+COUNTIFS('车控'!Q209:Q212,"Block") | AH11: 4 | AI11: =AF11 | AJ11: =AH11-AF11 | AK11: =AG11-AF11 | AL11: 字节-刘晓帝 FAIL | AM11: https://bytedance.larkoffice.com/record/B85brTuOieXghzct3MRcdy8dnFb https://bytedance.larkoffice.com/record/EX65rvfNmePZEbcDBZpcHXG1nrh | AP11: 车控 | AQ11: =AH11-E11 | AR11: @陈果果 进度表接api是1，模块表里研发进展1✅，研发备注4✅，实际是接了哪几个？上汽填n的3个api有两个写接口不支持、一个写接口状态返回成功，但是实际未执行，是本车无此功能吗？-充电口盖不支持，加油口盖关闭不支持，不支持的统一使用NLG话术兜底 @郑永超 进度表总case4，是否覆盖了4个api？-已完成
B12: 冰箱 | C12: 已完成 | D12: 50 | E12: 50 | F12: =G12/E12 | G12: 50 | H12: =E12-G12 | I12: 50 | J12: =I12/E12 | K12: 04.09、4.10： 上汽：打开 / 关闭冰箱设置页面； 字节：云端不下发：冰箱离车工作时长设置、冰箱离车工作周期设置、冰箱上电自动开启开关、冰箱制冰脱冰开关、冰箱遗留物品检测开关、冰箱净味杀菌开关FC问题待修复 -- 字节。 05.19：@杨忠谕验证下制冰 脱冰功能，验证失败hmi点击无反应，以提供日志给上汽，反馈需要底软排查。 05.26：待跟踪上汽底软问题修复 0611 上汽反馈需要刷冰箱版本，今日刷了275，明日刷254和319 0615 上汽接口已ok，争取0616提测/0622 已开发完，真车排队自测:自测通过/0629 客户端已提测/0630制冰脱冰测试已通过 0703 8个0627❌ | O12: =P12/E12 | P12: 50 | Q12: =E12-P12 | T12: 50 | U12: =T12/E12 | V12: =E12-T12 | W12: P0 | X12: ✅ | Y12: 05.04 | Z12: @杨忠谕 | AA12: @谢一鸣 | AB12: =AG12/AH12 | AC12: =AG12 | AD12: =E12-AC12 | AE12: =AF12/AG12 | AF12: =COUNTIFS('车控'!Q213:Q262,"✅") | AG12: =COUNTIFS('车控'!Q213:Q262,"✅")+COUNTIFS('车控'!Q213:Q262,"❌")+COUNTIFS('车控'!Q213:Q262,"Block") | AH12: 50 | AI12: =AF12 | AJ12: =AH12-AF12 | AK12: =AG12-AF12 | AL12: 字节-郑永超 FAIL（基于研发自测进度，fail项目主要是TTS播报错误） | AM12: https://bytedance.larkoffice.com/record/GP1Rr90c2enYeHcUmYoc8B9enbb https://bytedance.larkoffice.com/record/VJyCr8977eSziIcE43OcjB6lnyd https://bytedance.larkoffice.com/record/WJ8vr2RzOeMAOecBxq6c5Kjknxb https://bytedance.larkoffice.com/record/YC7PrLFt0eETL5coKrBccV2un27 https://bytedance.larkoffice.com/record/D7ggrwtCledBrIcYQYlcpyRhnDd | AP12: 车控 | AQ12: =AH12-E12 | AR12: @杨忠谕@郑永超 模块表里已接api测试进展❌的api的修复进度？-已完成 | AU12: 周二 | AV12: 3
B13: 晕动舒缓显示 | C13: 已完成 | D13: 9 | E13: 9 | F13: =G13/E13 | G13: 9 | H13: =E13-G13 | I13: 9 | J13: =I13/E13 | K13: 4.10 字节：fc不支持 4.27 等待自测 5.06 广播自测成功；实车FC没有下发 | O13: =P13/E13 | P13: 9 | Q13: =E13-P13 | T13: 9 | U13: =T13/E13 | V13: =E13-T13 | W13: P2 | X13: ✅ | Y13: 待产品明确 4.28 @廖婉婷 汪帅 4.30 广播自测成功；实车FC没有下发 | Z13: @余明明 | AA13: @高宇新 | AB13: =AG13/AH13 | AC13: =AG13 | AD13: =E13-AC13 | AE13: =AF13/AG13 | AF13: =COUNTIFS('车控'!Q263:Q271,"✅") | AG13: =COUNTIFS('车控'!Q263:Q271,"✅")+COUNTIFS('车控'!Q263:Q271,"❌")+COUNTIFS('车控'!Q263:Q271,"Block") | AH13: 9 | AI13: =AF13 | AJ13: =AH13-AF13 | AK13: =AG13-AF13 | AL13: 字节-谢军军 PASS | AP13: 车控 | AQ13: =AH13-E13
B14: 后排吸顶屏 | C14: 已完成 | D14: 7 | E14: 7 | F14: =G14/E14 | G14: 7 | H14: =E14-G14 | I14: 7 | J14: =I14/E14 | K14: 05.19：@刘敬思在275实车上验证下打开关闭及角度调节。 05.26：254实车不支持 0528 @方令平推进实车问题 0615 、0622开发都提测了，追测试郑永超确认测试进展 | N14: linkservicemanager2.0_is4pr_is4gr.pdf linksettingmanager-0.0.1_4-20251222.070545-1.jar:https://bytedance.larkoffice.com/file/NQTLb6yhvolgJ6xCTNUcUDqzn9c | O14: =P14/E14 | P14: 7 | Q14: =E14-P14 | R14: 04.15：实车不支持后排屏角度调节。 04.16：PP基线（4.0.5）的屏控支持，待更新版本验证， 需要更新实车配置字 -- 0421 完成 @邴岱一和配置字验证不通过。 04.28：验证不通过，DNA-658 | S14: 46133 | T14: 7 | U14: =T14/E14 | V14: =E14-T14 | W14: P0 | X14: ✅ | Y14: 04.22 当前开发完毕待验证了 | Z14: @高宇新 | AA14: @田高琳 | AB14: =AG14/AH14 | AC14: =AG14 | AD14: =E14-AC14 | AE14: =AF14/AG14 | AF14: =COUNTIFS('车控'!Q272:Q278,"✅") | AG14: =COUNTIFS('车控'!Q272:Q278,"✅")+COUNTIFS('车控'!Q272:Q278,"❌")+COUNTIFS('车控'!Q272:Q278,"Block") | AH14: 7 | AI14: =AF14 | AJ14: =AH14-AF14 | AK14: =AG14-AF14 | AL14: 字节-郑永超 FAIL | AM14: https://bytedance.larkoffice.com/record/Eunmr4LB4eJFXrcxyVlcb1qun6c | AP14: 车控 | AQ14: =AH14-E14 | AR14: @刘敬思 进度表接7个api，模块表5个api写待实车测试，确认后更新？-0526实车254不支持后排吸顶屏，待复测更新 | AU14: 周二 | AV14: 4
B15: 驾驶模式 | C15: 已完成 | D15: 11 | E15: 9 | F15: =G15/E15 | G15: 9 | H15: =E15-G15 | I15: 9 | J15: =I15/E15 | K15: 03.05： 1sdk没写调用哪个manager模块？2setEptTorqueCustMode对应参数值是啥？ setSteeringCustMode对应参数值值是啥？ setSuspensionSts对应参数值值是啥？ 以下功能在SDK内没找到对应API： 退出驾驶模式 语音控制动力响应 语音控制转向手感 语音控制悬架阻尼 语音控制恢复标准 03.17：1驾驶模式切换为空时调用关闭驾驶模式是否正确2页面无响应 3.19：驾驶模式页面无响应，驾驶模式为“切换驾驶模式为空”时调用的是“退出驾驶模式”是否正确 3.20问题同上，抓日志给上汽排查 3.23tts播报问题3.26已解决完成 3.27 更新sdk之后，悬架阻尼sdk接口有问题 03.31：HMI无状态显示实际控制效果。 @刘敬思查一下悬架阻尼接口的参数，是否支持三种控制项。如果有问题，微信群求助。 驾驶模式（雪地）调用API入参返回值待排查@刘敬思 4.2 待自测，已删除切换退出驾驶模式需求，已删除多余驾驶模式，悬架阻尼待自测，，添加仅主驾可操作功能 04.02、4.27：字节：转向手感fc不支持，接口对接进行中 上汽：悬架阻尼只有智慧悬架，但实际prd及技术实现包含悬架阻尼设置为舒适/标准/运动 0413 @杨忠谕:上汽说没有退出功能只有切换功能，不做打开关闭功能,280\281 4.23动力响应设置为舒适/标准/运动返回值3010015待上汽排查4.27驾驶模式切换舒适模式UI跳转到晕动舒缓模式，悬架阻尼和动力响应UI无变化4.28悬架阻尼和动力响应UI无变化 0506:驾驶模式悬架阻尼切换到运动返回resultCode=3000005 0512:转向手感待自测，自测不通过 513 抓日志排查,自测不通过排查中 515，05.26：283“方向盘助力调节”FC下发参数error，待云端排查/0608https://bytedance.larkoffice.com/record/WtndrrGeye5iX2cyOPycM3nOnTh 敬思反馈待自测 0528 @刘敬思: 反馈 周怀君 说这个“语音控制悬架阻尼”api先不用管/0608 敬思反馈当时测的时候可能是车的版本问题，时通时不通，加上模块表里ep车备注“只有智慧模式”太久远了，敬思再去车上验证一下，如果当前版本是好的，就提测 0611fc下发value错误，转向手感切换到舒适下发的参数是标准，切换到运动下发的沉稳，切换到标准下发的标准，上汽语义协议和实车上的模式不一致的问题，需要左晨确认下是修改协议还是做映射关系，bug单recvjua8GBsmzg recvm7pnoeeQw8/0618 左晨在bug里评论，请客户端同学做协议的参数值做适配。舒适=轻盈，运动=沉 稳，标准=标准。@刘敬思: / 0622 已开发完，真车排队自测 0615 除了上面转向手感，其他已提测，与测试郑永超确认测试进展 0622 275实车测试转向手感切换为运动/标准成功切换，切换为舒适，fc参数下发为标准切换失败/0629 recvjua8GBsmzg 服务端已修复，待敬思验证 0629验证已通过 0703 1个待测试 郑永超今晚发版点检的时候验 0706 永超反馈测试已通过，待更新表格 | N15: 03.05： @刘敬思先找吴佳军反馈。 03.17：待上汽排查 03.18：@刘敬思修改代码再验证。 3.19： 驾驶模式页面无响应，驾驶模式为“切换驾驶模式为空”时调用的是“退出驾驶模式”是否正确 03.23：权限SDK群里要一下@刘敬思 03.23：@周怀君提供权限SDK 03.24：权限SDK提供后无效，待上汽继续支持。3.26已解决完成 | O15: =P15/E15 | P15: 9 | Q15: =E15-P15 | R15: 04.15：制动控制 - 自动驻车，HMI回弹。解决计划时间4.0.7 04.16：需要拖回安亭做标定后，才能支持 04.22: 岱一 4.0.7版本复测 @邴岱一（254测试通过，253FAIL）0422：新问题-电子稳定系统回弹 | S15: 253实车需拖回安亭待标定，此功能先用254车验证，不block工作。 | T15: 9 | U15: =T15/E15 | V15: =E15-T15 | W15: P0 | X15: ✅ | Y15: 5月9号 | Z15: @高宇新 | AA15: @田高琳 | AB15: =AG15/AH15 | AC15: =AG15 | AD15: =E15-AC15 | AE15: =AF15/AG15 | AF15: =COUNTIFS('车控'!Q279:Q289,"✅") | AG15: =COUNTIFS('车控'!Q279:Q289,"✅")+COUNTIFS('车控'!Q279:Q289,"❌")+COUNTIFS('车控'!Q279:Q289,"Block") | AH15: 9 | AI15: =AF15 | AJ15: =AH15-AF15 | AK15: =AG15-AF15 | AL15: 上汽-FAIL 字节-郑永超 FAIL | AM15: https://bytedance.larkoffice.com/record/Bx45rDZv1eg1IOcKN2xci1b3nBd https://bytedance.larkoffice.com/record/XTdSr1uKTeSfTHcqTcVcqiTRnfe | AP15: 车控 | AQ15: =AH15-E15 | AR15: @刘敬思语音控制悬架阻尼api备注需双方需求对齐功能，具体进展？- @郑永超 进度表总case9完全通过，覆盖哪些api？更新模块表测试进展列-已完成
B16: 驾驶设置 | C16: 【火山】待测试 | D16: 8 | E16: 8 | F16: =G16/E16 | G16: 8 | H16: =E16-G16 | I16: 8 | J16: =I16/E16 | K16: 1.能量回收设置为高中低 @guixiang 反馈说权限问题 需加白名单@田高琳 03.31：@田高琳能量回收高中低控制问题，待提供log给guixiang排查。 04.02、4.10：剩余5功能，待FC支持。 (已补充至文档) 4.14 @田高琳今天补充在FC问题清单 已补充 4.21 能量回收设置为自适应，HMI也缺失 发动机维修模式（排放检测模式）开关，实车不支持 0504 @田高琳 :上汽桂祥反馈无该需求288 发动机维修模式、动力源模式FC还不支持 @左晨 5.9 能量回收设置为自适应 自行找产品确认好，不支持就TTS兜底；产业要求TTS兜底，等FC能下发之后兜底 0518：发动机维修模式FC不支持 @左晨 05.26：2个api 293、294 未收到FC 0527:待研发刷新。 0528 2个api 293、294 @尹泽陆 确认接口是否可用/@尹泽陆 288行“上汽桂祥反馈无该需求” 接兜底 0603 ”语音控制发动机维修模式-打开发动机维修模式、关闭发动机维修模式“FC无法下发，已反馈 0608 泽陆今日复验：FC无法下发，已反馈 0615 泽陆今天再试一下，如果没好就把原来的bug填进来；开发目前名下无bug，打开关闭某动力源模式测试❌与测试郑永超确认进展/0616 泽陆：等debug车回来/ fc已有，如果下发有问题找算法 0618 1个api（语音控制发动机维修模式），验证FC无法下发，已反馈云端 0622 研发名下bug今天可修复，真车排队验证 0706 再催泽民 7/7 泽民说添加个动态示例就能解决，会尽快解决 0708 泽民说已经好了，让他把meego单给泽陆，已通知泽陆0709发版后验一下 0720 meego票泽民已解决，待泽陆确认结果 | N16: 03.23：权限SDK群里要一下@田高琳 03.23：@周怀君提供权限SDK 03.24：权限SDK提供后无效，待上汽继续支持。 03.30：集成上汽签名包后，整体验一下权限问题。@田高琳 | O16: =P16/E16 | P16: 8 | Q16: =E16-P16 | R16: 04.15：实车不支持发动机维修模式 04.16：IS4PR车->排放检测模式，按键置灰无法点击 ---待反馈解决计划@董晓颖 04.21：@邴岱一上高压去验证。 - 已验证通过 | T16: 6 | U16: =T16/E16 | V16: 5 | W16: P0 | X16: ✅ | Y16: 4.22 开发完毕待自测了 | Z16: @尹泽陆 | AA16: @谢一鸣 | AB16: =AG16/AH16 | AC16: =AG16 | AD16: =E16-AC16 | AE16: =AF16/AG16 | AF16: =COUNTIFS('车控'!Q290:Q297,"✅") | AG16: =COUNTIFS('车控'!Q290:Q297,"✅")+COUNTIFS('车控'!Q290:Q297,"❌")+COUNTIFS('车控'!Q290:Q297,"Block") | AH16: 5 | AI16: =AF16 | AJ16: =AH16-AF16 | AK16: =AG16-AF16 | AL16: 上汽 （待对接进度为100%，上汽在测试） FAIL 字节-刘晓帝 | AM16: https://bytedance.larkoffice.com/record/ASFBrTYvXe7Zu1cYU5RcfcqcnVf https://bytedance.larkoffice.com/record/KYCYrOrLXetbA6cuDf9cEN9bnpd https://bytedance.larkoffice.com/record/DN8OrxDeOezpLDcWgSpcl5EynlS https://bytedance.larkoffice.com/record/OR4KrHm0DefpaacoiyXcrtFQneh https://bytedance.larkoffice.com/record/GcTVrAyDNewX0rc22L9c71ADnlg https://bytedance.larkoffice.com/record/KnMWr4BtieGVDIcT8eTcIwmVnKc https://bytedance.larkoffice.com/record/Qg0SrLgAwe2Du6cQSzQckGhennK https://bytedance.larkoffice.com/record/KcEfrdl6He8y86c3yymczsl6nVe https://bytedance.larkoffice.com/record/UgDRr5xMweJZnIcKKWFcfusIntf | AP16: 车控 | AQ16: =AH16-E16
B17: 摄像头相关 | C17: 【火山】待问题修复 | D17: 43 | E17: 43 | F17: =G17/E17 | G17: 43 | H17: =E17-G17 | I17: 43 | J17: =I17/E17 | K17: 1、打开 Carlog 应用使用原生跳转需要提供包名 2、打开相册使用原生跳转提供相关action 3、OMS摄像查看开关不下发FC（字节内部） 4、哨兵模式接口调用失败 5、驾驶员疲劳监测打开失败 03.27 摄像头OMS预览页面之类的没有 04.02：PP 4.0.3版本可测试验证。 04.16: 行车影像设置页面跳转无反应 04.20：除了以上三项都已经解决完毕 0422：@赵明珠刷新好最新状态 04.22:今天 253实车摄像头有问题，没有画面 04.24:释放新接口待接入 0506：dvr信号不稳定 0506：carlog拍照录像提示需要插入U盘 0507：dvr端状态拿不到信号 字节：缺FC 0519：端状态信号不稳定，包含下述3类 ~ 上汽 余良德 一般录像开关信号：onNormalRecordSwitchStatus 录音开关信号：onAudioRecordStatus OMS信号：onSwitchStatusChange 05.26：问题同05.19，推进上汽反馈排查。 05.27：接口使用问题：微信群搜索“就是用enum转int就行” 0603 u盘（c口128g）测试阻碍的问题暂时挂起，等p基线上了之后再验证（2个api，录像 - 短视频录像、控制 DVR - 设置录制时长） 0528 313、316两行api，fc不下发 请产品@廖婉婷支持/0602 张王成已清除313、316fc不下发的备注，316已接 还差用U盘验证的2个接口 06.16 忠谕:摄像头有三个新增的需求但是相对应的接口还没提供已在微信群中沟通。/0622 接口问题已问怀君等反馈 0706已自测通过待更新表格提测 | N17: 1&2待上汽定点；待上汽反馈@周怀君 4&5.@赵明珠在微信群和上汽接口同事「guixiang」沟通预期表现。 03.11： 4&5待有控制页面提供后再验证。0312 上汽预计本周提供@赵明珠 03.16： 摄像头HMI出图问题，预计下周版本解决。 03.23：PP 4.0.X版本解决，待「guixiang」跟进争取本周解决。 03:26： 在台架4.0.2版本接入OMS/DMS尝试推apk验证；@桂祥&周毅 Carlog功能8条，排期4/30交付 非接口需求：6条 打开页面2条已提供跳转能力接口 关闭页面2条预计4/16和字节沟通开发方案，4/30完成交付 | O17: =P17/E17 | P17: 43 | Q17: =E17-P17 | R17: 04.09：PPV1实车摄像头相关控制及取图失效。 04.13：舱内OMS*2 + 舱外AVCamr_F3（前120度周视） + 舱外 AVCamr_R（后周视）---04.25提供 04.15：只支持前排查看。HMI 后排查看等控制，无响应。 04.16: 开发排期4.22开发完成 04.28：VQA功能依赖摄像头取图能力，经常出现问题周毅让我们重启车机试一试~反馈是暂时不会推动解决稳定性的问题。---请上汽内部推动解决。 04.30：OMS概率取黑白图，非持续彩色图。 | S17: 46134 | T17: 43 | U17: =T17/E17 | V17: =E17-T17 | W17: P0 | X17: ✅ | Y17: 05.09 | Z17: @杨忠谕 | AA17: @赵明珠 | AB17: =AG17/AH17 | AC17: =AG17 | AD17: =E17-AC17 | AE17: =AF17/AG17 | AF17: =COUNTIFS('车控'!Q300:Q342,"✅") | AG17: =COUNTIFS('车控'!Q300:Q342,"✅")+COUNTIFS('车控'!Q300:Q342,"❌")+COUNTIFS('车控'!Q300:Q342,"Block") | AH17: 37 | AI17: =AF17 | AJ17: =AH17-AF17 | AK17: =AG17-AF17 | AL17: 上汽 FAIL 字节-郑永超 FAIl | AM17: https://bytedance.larkoffice.com/record/KUAHrWiGfedqLFcpJCKcFrjen9g https://bytedance.larkoffice.com/record/RBnvrSFwNeLkNPc6qq0cOPe7nfb https://bytedance.larkoffice.com/record/UhDrrZyHGenZjQcUaY3ciiHkngb https://bytedance.larkoffice.com/record/QhimrMdH4elYrQcOtAscuECTncc https://bytedance.larkoffice.com/record/Qvzjr1p6xetzHDcusklceEj7nrd | AP17: 车控 | AQ17: =AH17-E17 | AR17: @张王成进度表接api41，模块表研发进展只有40✅，请确认并更新？- 已更新，只有40 @张王成 两个fc不下发313、316，下一步做什么？1个302备注需要U盘，其他有的也备注了需要u盘但是也接了，这一条按照之前的做法接 | AS17: 1
B18: 维保 | C18: 已完成 | D18: 2 | E18: 2 | F18: =G18/E18 | G18: 2 | H18: =E18-G18 | I18: 2 | J18: =I18/E18 | K18: 从端状态信号对接获取 左晨0415：研发把 维保的信息收集到上报即可。整体需求与车况随心问相同，纳入到车况随心问中。 4.16待西钺提供端状态信息。 4.17待左晨找上汽产品对齐，因上汽反馈维保信息获取不到 4.20:左晨答复上汽的产品了， 查询类功能，要打开页面我们做不了。 上汽还没回复 05.26：上汽已提供ZoneAPI，待开发验证接口状态。 05.27: 0527确认API，0529完成开发； 06.01:需上汽侧把实车数据录入云端后才可查看数据，已反馈，待回复解决时间。 上汽怀君 0602 已追怀君，等反馈/怀君：云端在确认中，下午给反馈 0603 追怀君，暂未反馈 0614 与周怀君确认，他还在推动解决/ 0616 依旧 7/7 jira bug单更新，上汽侧评论7/6提交代码，6.0.1（7/7）版本可修复，已通知忠谕7/8验一下 0708 忠谕反馈今晚验 0710 忠谕验证上汽端有问题 | N18: 维保信息在云端，需要云云对接 1. 维保页面显示IP5PM项目开发未完成，DM负责开发 -- IP5PM 项目需要DM 确认 2. 接口需要DM提供云端接口 | O18: =P18/E18 | P18: 2 | Q18: =E18-P18 | R18: 维保，不涉及实车验证。 | T18: 2 | U18: =T18/E18 | V18: =E18-T18 | W18: P2 | Y18: 06.15 | Z18: @杨忠谕 | AA18: @余明明 | AB18: =AG18/AH18 | AC18: =AG18 | AD18: =E18-AC18 | AE18: =AF18/AG18 | AF18: =COUNTIFS('车控'!Q343:Q344,"✅") | AG18: =COUNTIFS('车控'!Q343:Q344,"✅")+COUNTIFS('车控'!Q343:Q344,"❌")+COUNTIFS('车控'!Q343:Q344,"Block") | AH18: 2 | AI18: =AF18 | AJ18: =AH18-AF18 | AK18: =AG18-AF18 | AL18: 字节-刘晓帝 | AP18: 车控 | AQ18: =AH18-E18 | AR18: @杨忠谕 进度表备注api已确认，请更新模块表L列接口识别-
B19: 制动 | C19: 【火山】待问题修复 | D19: 8 | E19: 8 | F19: =G19/E19 | G19: 8 | H19: =E19-G19 | I19: 8 | J19: =I19/E19 | K19: 03.05： sdk未找到调用哪个manager？ 03.12： ①状态 制动页面无响应； ②自动驻车所有接口调用之后设置页面没响应。3.19制动页面无响应 3.20问题同上，抓日志给上汽排查 3.27 问题同上，上汽排查中 03.30：HMI上无法识别是否生效。 03.31 @刘敬思「舒适制动」提供log给guixiang分析设置是否成功。HMI待后续支持。 4.3、4.10 “自动驻车”待左晨确认“深踩”模式及“传统”模式需求；添加仅主驾可操作功能 4.14 上汽说有这个需求，左晨说没有这个需求，待产品确认 4.16待上汽需求更新prd,打开关闭自动驻车及深踩模式的需求prd =》04.20：prd未更新 4.21上汽：待上汽更新prd4.27UI关闭制动全部无响应4.28制动253车置灰无法点击 05.26：待guixiang反馈更新SDK 05.27：如微信群沟通，语音打开需要设置last模式 请开发@刘敬思用此方式确认 0601接口调用返回值没拿到，待微信群和开发沟通 0602待自测 0604:接口返回值无法使用，需要再跟客户沟通 0608 车控-制动-自动驻车开关 - 打开，敬思反馈待自测/0611 敬思验证通过，提测 0615、0622 开发已都提测，开发名下没有bug，追测试谢军军进展 | N19: 03.05： @刘敬思先找吴佳军反馈。 03.12： ①&②确认返回值，分析是API问题 or HMI问题。@刘敬思提供log包。 03.17： @周怀君找jiajun协调支持。 03.18：@刘敬思修改代码再验证。 3.19：制动页面无响应 03.23：权限SDK群里要一下@刘敬思 03.23：@周怀君提供权限SDK | O19: =P19/E19 | P19: 7 | Q19: =E19-P19 | R19: 04.09：PPV1实车HMI制动控制不可用。 04.16： 需要实车进行标定 04.21：编号254标定完成，待验证是否HMI可控制， 验证有按钮回弹， 测试开票跟进 - @董晓颖 04.22：预计4.0.8版本修复 | S19: 46141 | T19: 8 | U19: =T19/E19 | V19: =E19-T19 | W19: P0 | X19: ✅ | Y19: 2026/5/7 | Z19: @高宇新 | AA19: @余明明 | AB19: =AG19/AH19 | AC19: =AG19 | AD19: =E19-AC19 | AE19: =AF19/AG19 | AF19: =COUNTIFS('车控'!Q345:Q352,"✅") | AG19: =COUNTIFS('车控'!Q345:Q352,"✅")+COUNTIFS('车控'!Q345:Q352,"❌")+COUNTIFS('车控'!Q345:Q352,"Block") | AH19: 8 | AI19: =AF19 | AJ19: =AH19-AF19 | AK19: =AG19-AF19 | AL19: 上汽-FAIL 字节-王东旭-FAIL | AM19: https://bytedance.larkoffice.com/record/V9xGreDHke2mECcNdOycFZu4nhn | AP19: 车控 | AQ19: =AH19-E19 | AR19: @刘敬思 模块表“自动驻车开关 - 打开研发进展”为空是否因为“如微信群沟通，语音打开需要设置last模式”？后续解决人是谁？-待复测
B20: 仪表及其他 | C20: 【火山】待问题修复 | D20: 12 | E20: 12 | F20: =G20/E20 | G20: 12 | H20: =E20-G20 | I20: 12 | J20: =I20/E20 | K20: 1.查询剩余电量与屏幕上的不一致 查询车辆最大电量: int getBmsPackSocKWh(@NonNull FloatResult result); 看状态O P标记的N 查询最大续航里程:主动查询值 端状态缺失@陈西钺（没有该需求） 03.31：@田高琳「查询剩余电量与屏幕上的不一致」提供log微信群给guixiang分析。 4.3 、4.10 1.设置了切换仪表视图2012无反应 已抓日志给@guixiang 已提供给guixiang 0615 、0622开发均已提测且名下无bug，与测试军军确认bug | N20: 根据DNA1.0：场景感知状态信号库v2.5 文档O、P列状态对接。 03.05： @田高琳:在上述2.5版本上，补充需要的端状态信息。 @周怀君:协调回调接口的状态。 03.11： 查询剩余电量、查询剩余油量(混动)。回调接口已提供@田高琳:验证反馈。 查询车辆最大电量、查询最大续航里程。其他都按主动获取方式实现。 0324：缺一个仪表视图切换接口 0326： 已提供 | O20: =P20/E20 | P20: 12 | Q20: =E20-P20 | R20: 端状态信号，不涉及前置实车状态验证。 | T20: 12 | U20: =T20/E20 | V20: =E20-T20 | W20: P0 | X20: ✅ | Y20: 03.06 | Z20: @高宇新 | AA20: @田高琳 | AB20: =AG20/AH20 | AC20: =AG20 | AD20: =E20-AC20 | AE20: =AF20/AG20 | AF20: =COUNTIFS('车控'!Q353:Q364,"✅") | AG20: =COUNTIFS('车控'!Q353:Q364,"✅")+COUNTIFS('车控'!Q353:Q364,"❌")+COUNTIFS('车控'!Q353:Q364,"Block") | AH20: 12 | AI20: =AF20 | AJ20: =AH20-AF20 | AK20: =AG20-AF20 | AL20: 字节-郑永超 FAIL | AM20: https://bytedance.larkoffice.com/record/ZO7prbGb4e3tCVcBd4acBIY8n4d https://bytedance.larkoffice.com/record/CIb1rhN5wejVkGcg7VFcjmxUnkF https://bytedance.larkoffice.com/record/GhXVrH3tjeEPnycA4N8cl3A3n9i https://bytedance.larkoffice.com/record/JqFqrqo9XeVAq2cc28Scw9Yknbg https://bytedance.larkoffice.com/record/EDP2rGY7Re4uftcgFsmc87XXnLg https://bytedance.larkoffice.com/record/YmcYrm0ape8GgBc2Q8mcApEsnyh | AP20: 车控 | AQ20: =AH20-E20
B21: 内灯 | C21: 【火山】待问题修复 | D21: 25 | E21: 25 | F21: =G21/E21 | G21: 25 | H21: =E21-G21 | I21: 25 | J21: =I21/E21 | K21: 1. 氛围灯颜色调节，仅支持主题色的调节，不支持单色的调节，且仅支持预制的6种颜色 2.API已集成验证，待实车自测。 3. 氛围灯颜色不支持白色和灰色的调节 4.4.22 字节：氛围灯律动调节，mode返回不对，已提给算法 05.26：ZoneAPI已提供，但实车不可用（实车可用时间待上汽反馈-）。 待客户确认实车解决时间； 05.28：预估P基线的实车才有内灯功能； 0602 p基线预计0607之前（2个api，语音控制打开关闭阅读灯、语音控制阅读灯亮度调节），开发名下无bug，但有10个❌，与测试谢军军确认bug 0622 真车排队 0624 测试不通过，接口调用成功，实际阅读灯未执行，已同步上汽研发谭忠洲 0706 果果反馈语音与车机是通了，但是车上的灯有问题看不到物理效果，已拉群问汪帅、晓健、令平 7/7 hmi控灯有问题，我们与hmi一致即可提测，上汽2个bug是fixed和verifying，灯开关的问题上汽备注sop基线同步更新，让果果找上海同事车上试一下，1个api（语音打开关闭阅读灯）dna-1475 晓颖说明天问她，她找方俊确认日期 0708 已追晓颖等反馈/0709 晓颖反馈：等车基线升级到SOP基线 | N21: 03.10： @田高琳先在微信群找「guixiang」沟通确认。 03.12： SDK内API和表格中接口描述内容不一致。「guixiang」协调确认。 03.17：先按照SDK内容识别，@田高琳发微信群找guixiang确认。 P基线新增阅读灯条目2条，排期5/17 IS4PR-4163 D01_P05_M07_F05_内部灯光控制（全车型）_阅读灯开关_P基线 5/15:P基线SOA信号延期释放，推迟到5/21提供给字节 | O21: =P21/E21 | P21: 25 | Q21: =E21-P21 | T21: 25 | U21: =T21/E21 | V21: =E21-T21 | W21: P0 | X21: ✅ | Y21: 05.19 | Z21: @陈果果 | AA21: @杨忠谕 | AB21: =AG21/AH21 | AC21: =AG21 | AD21: =E21-AC21 | AE21: =AF21/AG21 | AF21: =COUNTIFS('车控'!Q365:Q389,"✅") | AG21: =COUNTIFS('车控'!Q365:Q389,"✅")+COUNTIFS('车控'!Q365:Q389,"❌")+COUNTIFS('车控'!Q365:Q389,"Block") | AH21: 23 | AI21: =AF21 | AJ21: =AH21-AF21 | AK21: =AG21-AF21 | AL21: 字节-郑永超 FAIL | AM21: https://bytedance.larkoffice.com/record/CksOrbqp7e6T44cIddfc4jevnIc https://bytedance.larkoffice.com/record/DQCfr7teLeHFOycHwQxcUZ6cnAe https://bytedance.larkoffice.com/record/J3rDrUbjKeMm4CcISQAc3XM7n2e | AP21: 车控 | AQ21: =AH21-E21 | AU21: 周二 | AV21: 6
B22: 外灯 | C22: 已完成 | D22: 22 | E22: 22 | F22: =G22/E22 | G22: 22 | H22: =E22-G22 | I22: 22 | J22: =I22/E22 | K22: 1.设置主灯模式setMasterLightMode方法和接口实际参数文档上的值对不上 0x0=OFF 0X1=SidePositionLight ON 0X2=DippedBeamLight ON 0X3=AUTO 实际的如右图 04.24：远光灯没有接口需求，语音兜底 屏控验证迎宾灯语通过 | N22: 03.10： @田高琳先在微信群找「guixiang」沟通确认。 03.12： SDK内API和表格中接口描述内容不一致。「guixiang」协调确认。 04.22：迎宾语开关，接口已支持，待释放版本验证 远光灯开关：语音兜底，引导手动操作 04.23：待0423 daily版本验证测试 04.24：屏控验证迎宾灯语通过 | O22: =P22/E22 | P22: 22 | Q22: =E22-P22 | R22: 04.08：大灯控制HMI回弹。 04.09：白天上车验证又正常。 | T22: 22 | U22: =T22/E22 | V22: =E22-T22 | W22: P0 | X22: ✅ | Y22: 04.28 | Z22: @陈果果 | AA22: @杨忠谕 | AB22: =AG22/AH22 | AC22: =AG22 | AD22: =E22-AC22 | AE22: =AF22/AG22 | AF22: =COUNTIFS('车控'!Q390:Q411,"✅") | AG22: =COUNTIFS('车控'!Q390:Q411,"✅")+COUNTIFS('车控'!Q390:Q411,"❌")+COUNTIFS('车控'!Q390:Q411,"Block") | AH22: 22 | AI22: =AF22 | AJ22: =AH22-AF22 | AK22: =AG22-AF22 | AL22: 上汽 FAIL 字节-郑永超 FAIL | AM22: https://bytedance.larkoffice.com/record/AVjmrT1x0e54YTcimwccMXgXnAh https://bytedance.larkoffice.com/record/XGForV0woeHNlScCLGYc1HIhnfh https://bytedance.larkoffice.com/record/NQkprBiDOe0BAxcuOAMcJRimnxK https://bytedance.larkoffice.com/record/E2KrrVPzRejKiocCITEcP5OonBc https://bytedance.larkoffice.com/record/CWXsrATm8eKEnDchg9xcEzganhb https://bytedance.larkoffice.com/record/RgtUrsNFoeOKIrcYXiZcvcqOn4f https://bytedance.larkoffice.com/record/DaYprgBAAeaCbXcXz99cJ2f2ngf https://bytedance.larkoffice.com/record/MJegrQllBeojuVcsyEpckmCynne https://bytedance.larkoffice.com/record/LtDdrptMxeeX5oc5SbYcoZ5pnGb https://bytedance.larkoffice.com/record/I1kNriL8te16QScNLcOcmvSRnUh https://bytedance.larkoffice.com/record/FT4GrvwLIeUzGJcLKRvcEkognIg https://bytedance.larkoffice.com/record/GbcuraHCweLtZ4cFFKLcAmdwntd https://bytedance.larkoffice.com/record/ABUkrOuGfeqwmBcIpOZc9c9unzC https://bytedance.larkoffice.com/record/GNiurc3TVeJoqgc8FdpcsZAOncb https://bytedance.larkoffice.com/record/P22rruNyEejDVbc8E9OcrEzPn8e | AP22: 车控 | AQ22: =AH22-E22
B23: 智能场景 | C23: 已完成 | D23: 1 | E23: 1 | F23: =G23/E23 | G23: 1 | H23: =E23-G23 | I23: 1 | J23: =I23/E23 | K23: 左晨0416：需要planner先区分下哪些能自己做，哪些要系统做。 依赖上汽提供knowhow。 智能场景中的打开关闭功能，Daniel反馈，不要用固定的控制执行。 这些给到豆包Planner去推理，当然场景提供给用户什么最好 因此智能场景部分的控制，我们就不对接了。 | O23: =P23/E23 | P23: 1 | Q23: =E23-P23 | T23: 1 | U23: =T23/E23 | V23: =E23-T23 | W23: P2 | Y23: 待产品澄清 @左晨 | Z23: @杨忠谕 | AA23: @田高琳 | AB23: =AG23/AH23 | AC23: =AG23 | AD23: =E23-AC23 | AE23: =AF23/AG23 | AF23: =COUNTIFS('车控'!Q412,"✅") | AG23: =COUNTIFS('车控'!Q412,"✅")+COUNTIFS('车控'!Q412,"❌")+COUNTIFS('车控'!Q412,"Block") | AH23: 1 | AI23: =AF23 | AJ23: =AH23-AF23 | AK23: =AG23-AF23 | AL23: 字节-郑永超 | AP23: 车控 | AQ23: =AH23-E23
B24: 个人中心 | C24: 【火山】待开发 | D24: 6 | E24: 6 | F24: =G24/E24 | G24: 6 | H24: =E24-G24 | I24: 6 | J24: =I24/E24 | K24: 4.14 开发需要自测完成，需大众提供账号才能自测现在扫描二维码显示“扫描的授权码未经过认证哦～” 4.18： 字节：导航账号登录、导航账号退出、人脸识别登录开关，fc不支持 0706 待忠谕验证fc是否已解决 0528 2个api@左晨：fc不支持的“语音控制导航账号切、换人脸识别登录账号”/ 0608 左晨说低优功能，他记下来再看。 不支持的，可以在功能 列表里， 标注为FC不支持。 0528 2个api（录入人脸识别信息、删除人脸识别信息） sop+3/ 7/7待忠谕建jira bug票（已告知） 7/6 2个api（语音控制导航账号切换、人脸识别登录账号开关）fc问题待忠谕7/7复验 0708 忠谕今晚验 0723 待忠谕验证/ 忠谕 0731 给结论 | L24: @杨忠谕 | M24: http://jira.z-onesoftware.com:8080/browse/DNA-2973 上汽票里反馈【pp基线已上限oms FaceId功能，目前版本均可验证】 | N24: 【语音控制导航账号切换】需求1条，P基线需求，排期4/30 | O24: =P24/E24 | P24: 0 | Q24: =E24-P24 | R24: 04.15：个人中心版本待升级，结合FaceID的个人中心APP，支持计划04.30。 | S24: 46141 | T24: 4 | U24: =T24/E24 | V24: =E24-T24 | W24: P2 | Y24: 05.04 | Z24: @杨忠谕 | AA24: @谢一鸣 | AB24: =AG24/AH24 | AC24: =AG24 | AD24: =E24-AC24 | AE24: =AF24/AG24 | AF24: =COUNTIFS('车控'!Q413:Q418,"✅") | AG24: =COUNTIFS('车控'!Q413:Q418,"✅")+COUNTIFS('车控'!Q413:Q418,"❌")+COUNTIFS('车控'!Q413:Q418,"Block") | AH24: 6 | AI24: =AF24 | AJ24: =AH24-AF24 | AK24: =AG24-AF24 | AL24: 字节-郑永超 | AM24: https://meego.larkoffice.com/telematics/issue/detail/7282835850 https://meego.larkoffice.com/telematics/issue/detail/7282835850 | AP24: 车控 | AQ24: =AH24-E24 | AR24: @杨忠谕 2个人脸不支持无法自测，下一步怎么办？2个FC不支持，现在是谁在解决啊？- 左晨
B25: 智能能量池 | C25: 已完成 | D25: 2 | E25: 2 | F25: =G25/E25 | G25: 2 | H25: =E25-G25 | I25: 2 | J25: =I25/E25 | K25: 04.27：调用无线充电和手机遗忘提醒接口，返回权限异常，重启试试（上汽已知问题，已起票） | O25: =P25/E25 | P25: 0 | Q25: =E25-P25 | T25: 2 | U25: =T25/E25 | V25: =E25-T25 | W25: P0 | Y25: 04.25 | Z25: @高宇新 | AA25: @余明明 | AB25: =AG25/AH25 | AC25: =AG25 | AD25: =E25-AC25 | AE25: =AF25/AG25 | AF25: =COUNTIFS('车控'!Q419:Q420,"✅") | AG25: =COUNTIFS('车控'!Q419:Q420,"✅")+COUNTIFS('车控'!Q419:Q420,"❌")+COUNTIFS('车控'!Q419:Q420,"Block") | AH25: 2 | AI25: =AF25 | AJ25: =AH25-AF25 | AK25: =AG25-AF25 | AL25: 字节-刘晓帝 PASS | AP25: 车控 | AQ25: =AH25-E25 | AR25: @张王成进度表已接是2，模块表研发进展为空，请确认并更新-已更新（0528）
A26: 系统设置 | B26: 声音 | C26: 【上汽】SDK文档接口实车卡点,【火山】待开发 | D26: 63 | E26: 50 | F26: =G26/E26 | G26: 45 | H26: =E26-G26 | I26: 45 | J26: =I26/E26 | K26: 1、jar目前存在问题，需要提供新的jar包（已在微信群中提出问题，等待反馈） 2、音量方法是否支持具体数值和百分比调节 3、接口文档没有头枕音响模式接口，SDK是否支持，支持的话请提供一下接口 4、没有找到低速行人提示音开关接口 5、没有K歌相关操作接口 6、语音控制蓝牙耳机音量，无法识别分区。 3.27：定义P0部分已接入完成。权限包已更新功能还是不行，待排查功能异常的其他原因@赵明珠 04.08、4.10：导航静音失败已在微信群反馈日志@赵明珠 4.14 开始对接剩余的非标绿的部分 04.20:导航禁音问题未反馈 04.22：导航静音问题，票已经到延峰手里，问题还在分析 04.24：问题还未回复 04.24：部分功能未给接口 04.28:未找到接口说的pdf文档（应用中间件Audio使用规范V1.0.pdf） 0507：车外喊话没声音 确认要调节耳机音量到总音量的 70% 么——5.9 自行找产品确认好有没有这个能力 找云端：首次下发、二次确认下发的FC和参数的区别 05.19：二次确认， @赵明珠验证反馈 头枕环绕调节，接口执行失败。 05.19：@赵明珠提供log给上汽分析 05.22:HMI页面未找到功能 0526 部分功能有接口调用异常问题，部分功能有FC 未下发问题，都以bug 票形式流转/0608 fc不下发的工单 0528 5个api“语音控制车外喊话 - 无麦 K 歌” 设置功能排期推迟到SOP+3/ 0707 告知泽陆尽快建jira bug票 0603 上汽给了新的接口文档，部分功能需要修改 0608 泽陆，预计剩余本周完成开发 0615 泽陆更新剩余接口开发进度 0618 K 歌功能开发中，其他功能待整理提测 0630 泽陆反馈走兜底，预计0703完成 0706 走兜底的5个已完成，待泽陆更新表格 0707 剩1个泽陆预计0709完成，还有一个在泽陆备注左晨反馈这个功能无需开发，在与左晨确认无需开发是否还需要测试 0707 整车声场模式与音量调节 - 整车声场模式与音量调节，左晨会删除这一行/泽陆还剩一个接口预计0709完成 0710 1个api（语音控制音量调节 -语音控制蓝牙耳机音量 - 蓝牙耳机音量保护功能）云端bug 0730 meego票已解决，待泽陆反馈 | L26: @李强 @尹泽陆 | M26: https://meego.larkoffice.com/telematics/issue/detail/7344391775?parentUrl=%2Ftelematics%2Fissue%2Fhomepage&openScene=4&tabKey=comment#comment | N26: 03.10： 上汽已提供“声音设置补充的sdk包（补充接口）”sound-1.0.8.jar 。待@赵明珠:验证。 03.11： 「guixiang」提供接口使用文档 03.12： 第4，未找到API；@guixiang 第5，待上汽排期 @guixiang。--- 无麦K歌计划04.20提供；车外喊话04.10提供。 第6，待上汽内部确认实车标配是否1个蓝牙芯片不分区。@ guixiang -- 调后排蓝牙耳机音量即可。 无麦K歌5条，排期4/24 - 设置功能排期推迟到SOP+3， 产品需求未拉齐 非接口需求：1条 打开页面需求6.5条，已提供能力 【语音控制声音设置项】有7条需求确认不支持语音控制， 【语音控制多媒体外放模式】需求确认不支持语音控制，语音话术兜底。 关闭页面需求0.5条，预计4/16和字节沟通开发方案，4/30完成交付 --0519：导航静音问题延锋已修复，待版本释放验证 | O26: =P26/E26 | P26: 29 | Q26: =E26-P26 | R26: 04.15： 不支持蓝牙耳机音量控制、车内声浪、安全带提示音、AudioPilot 噪声补偿、倒车自动降音开关、bose音效、车外喊话、多媒体外放、无麦 K 歌。 04.16：需要连接蓝牙耳机（仅后排）才支持音量控制； 无麦 K 歌 排期-4/24 -- 功能开发推迟到SOP +3 0421： 车内声浪 -- 整车不支持 安全带提示音 -- 整车不支持 AudioPilot 噪声补偿-- 整车不支持 倒车自动降音开关 -- 整车不支持 bose音效 -- 整车不支持 车外喊话 -- 接口已提供 多媒体外放-- 整车不支持 | S26: IS4PR实车不支持语音控制，请上汽产品更新PRD。 | T26: 45 | U26: =T26/E26 | V26: =E26-T26 | W26: P0 | X26: ✅ | Y26: 05.15 | Z26: @尹泽陆 | AA26: @赵明珠 | AB26: =AG26/AH26 | AC26: =AG26 | AD26: =E26-AC26 | AE26: =AF26/AG26 | AF26: =COUNTIFS('系统设置'!Q67:Q129,"✅") | AG26: =COUNTIFS('系统设置'!Q67:Q129,"✅")+COUNTIFS('系统设置'!Q67:Q129,"❌")+COUNTIFS('系统设置'!Q67:Q129,"Block") | AH26: 63 | AI26: =AF26 | AJ26: =AH26-AF26 | AK26: =AG26-AF26 | AL26: 字节-刘晓帝 | AM26: https://bytedance.larkoffice.com/record/SuwKra2WIemt0ncCrjvckCZBnPe https://bytedance.larkoffice.com/record/GUokrBw8FeM5GTckVr4cEQUan0e https://bytedance.larkoffice.com/record/FpVarjQL1etK2wcuvyvcII72nWe https://bytedance.larkoffice.com/record/SA2BrppIfeFDG8cFrAfc7ttvnUg https://bytedance.larkoffice.com/record/QmOQrFhNoesB1scYlDTcHZg2n2b https://bytedance.larkoffice.com/record/VzgXrHJ28e7aDpcA00GcTF2mnld https://bytedance.larkoffice.com/record/VwPirxnh8eRnihc4XrScBbcun3g https://bytedance.larkoffice.com/record/VtAdrUG7DeQT12cVK28cYJEyn2P https://bytedance.larkoffice.com/record/Kuejre0LFejN2WcXXePcQ8rVntc https://bytedance.larkoffice.com/record/Tg97rhktlet3uOcsBo5cWzjynhf | AP26: 系统设置 | AQ26: =AH26-E26 | AR26: @尹泽陆 模块表研发进展数据与进度表对不上，请确认并更新- 已更新 | AU26: 周二 | AV26: 8
B27: 系统设置开关 | C27: 已完成 | D27: 8 | E27: 6 | F27: =G27/E27 | G27: 6 | H27: =E27-G27 | I27: 6 | J27: =I27/E27 | K27: 0601 敬思遇到bug已在微信群找了上汽 桂祥，等反馈 0603上汽反馈不需要我们新增intent，原有接口可直接弹出二次确认弹框/0608 进度表写接8个，模块表有2个“无此需求”已问敬思什么情况 0608:2个api上汽研发反馈“打开蓝牙耳机开关”当前没有API接口，需与上汽产品确认 0622 A票问题已修复可复测 0702 问邹泽文上述情况如何推进，他说需要与上汽产品同事确认一下 0708 已追邹泽文，他已问上汽内部沟通，等反馈/泽文说问了，有这个功能，等泽文拉上汽研发进群沟通 0709 泽文拉了群，在与上汽研发确认 0710 宇新在确认上汽的反馈是否可用，今晚前给结论 0713 上汽产品邹泽文最终决定【开发反馈没有蓝牙耳机开关，先不做】 | N27: 3.17 目前只剩WiFi开关待验证3.18已跑通 | O27: =P27/E27 | P27: 6 | Q27: =E27-P27 | T27: 6 | U27: =T27/E27 | V27: =E27-T27 | W27: P0 | X27: ✅ | Y27: 03.13 | Z27: @高宇新 | AA27: @余明明 | AB27: =AG27/AH27 | AC27: =AG27 | AD27: =E27-AC27 | AE27: =AF27/AG27 | AF27: =COUNTIFS('系统设置'!Q2:Q9,"✅") | AG27: =COUNTIFS('系统设置'!Q2:Q9,"✅")+COUNTIFS('系统设置'!Q2:Q9,"❌")+COUNTIFS('系统设置'!Q2:Q9,"Block") | AH27: 6 | AI27: =AF27 | AJ27: 0 | AK27: =AG27-AF27 | AL27: 字节-刘晓帝 PASS | AP27: 系统设置 | AQ27: =AH27-E27
B28: 屏幕亮度 | C28: 已完成 | D28: 11 | E28: 11 | F28: =G28/E28 | G28: 11 | H28: =E28-G28 | I28: 11 | J28: =I28/E28 | K28: 1、getBackLightBrightness 获取屏幕亮度始终为0 0615、0622 开发名下无bug，测试有1个case没过，与测试刘晓帝确认bug | O28: =P28/E28 | P28: 11 | Q28: =E28-P28 | T28: 11 | U28: =T28/E28 | V28: =E28-T28 | W28: P0 | X28: ✅ | Y28: 03.13 | Z28: @谢一鸣 | AA28: @尹泽陆 | AB28: =AG28/AH28 | AC28: =AG28 | AD28: =E28-AC28 | AE28: =AF28/AG28 | AF28: =COUNTIFS('系统设置'!Q10:Q20,"✅") | AG28: =COUNTIFS('系统设置'!Q10:Q20,"✅")+COUNTIFS('系统设置'!Q10:Q20,"❌")+COUNTIFS('系统设置'!Q10:Q20,"Block") | AH28: 11 | AI28: =AF28 | AJ28: =AH28-AF28 | AK28: =AG28-AF28 | AL28: 上汽 FAIL 字节-刘晓帝 FAIL | AM28: https://bytedance.larkoffice.com/record/InxIryuKneOrkEc7gXxc8Ftvnzb https://bytedance.larkoffice.com/record/Yki8raciieLBemcU9DMcffK0nqd | AP28: 系统设置 | AQ28: =AH28-E28 | AR28: @刘晓帝 进度表100%，模块表测试状态还有❌，请确认并更新-已完成
B29: 屏保 | C29: 已完成 | D29: 6 | E29: 6 | F29: =G29/E29 | G29: 6 | H29: =E29-G29 | I29: 6 | J29: =I29/E29 | K29: 4.16： 6个功能控制接口返回值异常，已收集待上汽排查问题。 04.20：@刘敬思更新最新进展4.21待上汽分析bug 04.21：@刘敬思调整使用逻辑后自测 4.22 打开退出屏保仍有bug待上汽排查，切换屏保功能正常4.22屏保打开关闭，样式切换都已修复，但是253的车打开屏保始终进入黑色屏保样式 0527:@赵晓健@刘晓帝 确认完成测试时间 0615、0622 开发名下无bug，测试有2个case没过，与测试刘晓帝确认bug | O29: =P29/E29 | P29: 6 | Q29: =E29-P29 | T29: 6 | U29: =T29/E29 | V29: =E29-T29 | W29: P2 | Y29: 4.22 | Z29: @高宇新 | AA29: @余明明 | AB29: =AG29/AH29 | AC29: =AG29 | AD29: =E29-AC29 | AE29: =AF29/AG29 | AF29: =COUNTIFS('系统设置'!Q21:Q26,"✅") | AG29: =COUNTIFS('系统设置'!Q21:Q26,"✅")+COUNTIFS('系统设置'!Q21:Q26,"❌")+COUNTIFS('系统设置'!Q21:Q26,"Block") | AH29: 6 | AI29: =AF29 | AJ29: =AH29-AF29 | AK29: =AG29-AF29 | AL29: 字节-郑永超 FAIL | AM29: https://bytedance.larkoffice.com/record/RyfqrxP9jer9k0c4gkqcsjhSndb https://bytedance.larkoffice.com/record/WcAorFpQueI7lqcIZadcwbknnCd https://bytedance.larkoffice.com/record/G7xSrn6Bfe8crUcp8YAcV28rniH | AP29: 系统设置 | AQ29: =AH29-E29 | AR29: @刘晓帝 2条无此功能是否需要兜底测试？- 我也没看到研发备注走兜底回复呀
B30: 主题切换 | C30: 已完成 | D30: 5 | E30: 5 | F30: =G30/E30 | G30: 5 | H30: =E30-G30 | I30: 5 | J30: =I30/E30 | K30: 4.20缺jar包待上汽提供4.21待上汽分析bug 04.21：@刘敬思调整使用逻辑后自测4.22主题切换不生效待上汽排查 4.22字节：主题切换逻辑bug待排查修复4.23已修复bug 4.24UI切换到黑夜模式bug 0615、0622 开发名下无bug，测试有1个case没过，与测试刘晓帝确认bug | O30: =P30/E30 | P30: 5 | Q30: =E30-P30 | T30: 5 | U30: =T30/E30 | V30: =E30-T30 | W30: P2 | Y30: 04.24 | Z30: @高宇新 | AA30: @余明明 | AB30: =AG30/AH30 | AC30: =AG30 | AD30: =E30-AC30 | AE30: =AF30/AG30 | AF30: =COUNTIFS('系统设置'!Q27:Q31,"✅") | AG30: =COUNTIFS('系统设置'!Q27:Q31,"✅")+COUNTIFS('系统设置'!Q27:Q31,"❌")+COUNTIFS('系统设置'!Q27:Q31,"Block") | AH30: 5 | AI30: =AF30 | AJ30: =AH30-AF30 | AK30: =AG30-AF30 | AL30: 字节-刘晓帝 FAIL | AM30: https://bytedance.larkoffice.com/record/CfbTrbouhei7IGcLZficQk1TnPc https://bytedance.larkoffice.com/record/U5PmrChWJekPLRcK4zXcJuk8nIf | AP30: 系统设置 | AQ30: =AH30-E30 | AR30: @刘敬思 进度表已接5，模块表研发进展“进行中”，请确认并更新-
B31: 壁纸切换 | C31: 已完成 | D31: 4 | E31: 4 | F31: =G31/E31 | G31: 4 | H31: =E31-G31 | I31: 4 | J31: =I31/E31 | K31: 已具备 04.22 左晨：功能一重新打开，需要再确认接口，如有继续开发，如无则标记block 04.22 05.05 05.15 功能1 缺少 FC 05.26：验证“壁纸设置”FC函数 06.01 “壁纸设置”FC函数验证通过，功能开发完毕 0615、0622 开发名下无bug，测试有1个case没过，与测试刘晓帝确认bug | O31: =P31/E31 | P31: 4 | Q31: =E31-P31 | T31: 4 | U31: =T31/E31 | V31: =E31-T31 | W31: P2 | Z31: @尹泽陆 | AA31: @樊晓天 | AB31: =AG31/AH31 | AC31: =AG31 | AD31: =E31-AC31 | AE31: =AF31/AG31 | AF31: =COUNTIFS('系统设置'!Q32:Q35,"✅") | AG31: =COUNTIFS('系统设置'!Q32:Q35,"✅")+COUNTIFS('系统设置'!Q32:Q35,"❌")+COUNTIFS('系统设置'!Q32:Q35,"Block") | AH31: 4 | AI31: =AF31 | AJ31: =AH31-AF31 | AK31: =AG31-AF31 | AL31: 字节-郑永超 FAIL | AP31: 系统设置 | AQ31: =AH31-E31
B32: 分屏 | C32: 已完成 | D32: 3 | E32: 2 | F32: =G32/E32 | G32: 2 | H32: =E32-G32 | I32: 2 | J32: =I32/E32 | K32: 4.21：已在微信群沟通。 上汽产品侧反馈有需求，研发反馈没有需求。 已经让他们做信息拉齐了。 上汽接口block---上汽SRS反馈无此需求，待上汽产品澄清。 05.19：变更内容按新逻辑排期。本范围已完成。 | O32: =P32/E32 | P32: 3 | Q32: =E32-P32 | T32: 2 | U32: =T32/E32 | V32: =E32-T32 | W32: P2 | Y32: 05.05 | Z32: @杨忠谕 | AA32: @高宇新 | AB32: =AG32/AH32 | AC32: =AG32 | AD32: =E32-AC32 | AE32: =AF32/AG32 | AF32: =COUNTIFS('系统设置'!Q38:Q39,"✅") | AG32: =COUNTIFS('系统设置'!Q38:Q39,"✅")+COUNTIFS('系统设置'!Q38:Q39,"❌")+COUNTIFS('系统设置'!Q38:Q39,"Block") | AH32: 2 | AI32: =AF32 | AJ32: =AH32-AF32 | AK32: =AG32-AF32 | AL32: 字节-郑永超 FAIL | AM32: https://bytedance.larkoffice.com/record/S1CprG4p4e8Ko7ct8tFcOSzQnZf | AP32: 系统设置 | AQ32: =AH32-E32 | AR32: @王东旭1条无此功能是否需要兜底测试？-已完成
B33: 热点 | C33: 【火山】待问题修复 | D33: 4 | E33: 4 | F33: =G33/E33 | G33: 4 | H33: =E33-G33 | I33: 4 | J33: =I33/E33 | K33: 接口int参数对应几，切换频段为2.4或5hz 03.12： 热点接口奔溃3.18已解决 3.23： API返回值问题，导致tts播报异常。3.27已解决 4.2二级判断添加，已完成 0615、0622 开发名下无bug，测试有1个case没过，与测试王东旭确认bug | N33: 03.05： int型对应频段映射关系说明。@刘敬思按常量传值。 03.12: 调整使用方式后尝试 3.17 sdk执行异常，待抓日志让上汽分析@刘敬思 待guixiang协助分析反馈。 03.23：待「guixiang」分析反馈。 03.24：@刘敬思debug再分析 | O33: =P33/E33 | P33: 4 | Q33: =E33-P33 | T33: 4 | U33: =T33/E33 | V33: =E33-T33 | W33: P0 | X33: ✅ | Y33: 03.06 | Z33: @高宇新 | AA33: @尹泽陆 | AB33: =AG33/AH33 | AC33: =AG33 | AD33: =E33-AC33 | AE33: =AF33/AG33 | AF33: =COUNTIFS('系统设置'!Q41:Q44,"✅") | AG33: =COUNTIFS('系统设置'!Q41:Q44,"✅")+COUNTIFS('系统设置'!Q41:Q44,"❌")+COUNTIFS('系统设置'!Q41:Q44,"Block") | AH33: 4 | AI33: =AF33 | AJ33: =AH33-AF33 | AK33: =AG33-AF33 | AL33: 上汽 FAIL 字节-王东旭 FAIL | AM33: https://bytedance.larkoffice.com/record/McRSr2rVBeIG93cOKO0cmSnKnjM | AP33: 系统设置 | AQ33: =AH33-E33
B34: 蓝牙 | C34: 已完成 | D34: 4 | E34: 4 | F34: =G34/E34 | G34: 4 | H34: =E34-G34 | I34: 4 | J34: =I34/E34 | K34: 03.12： 1始终播放音频有bug 2打开蓝牙可被发现开关是否同时开启打开蓝牙开关？关闭蓝牙可被发现开关是否同时关闭蓝牙开关？ 3.关闭蓝牙可被发现开关，调用之后不生效，有时候会把蓝牙开关关闭 3.19蓝牙耳机需求 待确认 3.20同上需求待左晨确认 3.23： API返回值问题，导致tts播报异常。3.26已解决完成 4.2二级判断添加，已完成 | N34: 1左图缺接口，蓝牙耳机音量接口支持，1和3非zoneapi需求 2始终播放手机音频开关Settings.Global.BT_PLAY_PHONE_MEDIA_SWITCH解决中 03.12: 调整使用方式后尝试 3.17 耳机开关的逻辑待产品确认，上汽反馈只有开关，后排只有连接 @刘敬思 03.17： 蓝牙耳机开关需求，待PO反馈双方沟通结果。 03.18：明天17:00对PRD变更内容澄清会。3.19蓝牙耳机需求 待确认 03.23：待「guixiang」分析反馈。 03.24：@刘敬思debug再分析 | O34: =P34/E34 | P34: 4 | Q34: =E34-P34 | T34: 4 | U34: =T34/E34 | V34: =E34-T34 | W34: P0 | X34: ✅ | Y34: 03.06 | Z34: @高宇新 | AA34: @尹泽陆 | AB34: =AG34/AH34 | AC34: =AG34 | AD34: =E34-AC34 | AE34: =AF34/AG34 | AF34: =COUNTIFS('系统设置'!Q45:Q48,"✅") | AG34: =COUNTIFS('系统设置'!Q45:Q48,"✅")+COUNTIFS('系统设置'!Q45:Q48,"❌")+COUNTIFS('系统设置'!Q45:Q48,"Block") | AH34: 4 | AI34: =AF34 | AJ34: =AH34-AF34 | AK34: =AG34-AF34 | AL34: 上汽 PASS 字节-王东旭 PASS | AP34: 系统设置 | AQ34: =AH34-E34 | AR34: @王东旭 进度表总case数1，未通过4，请确认并更新-已完成
B35: 时间格式 | C35: 已完成 | D35: 2 | E35: 2 | F35: =G35/E35 | G35: 2 | H35: =E35-G35 | I35: 2 | J35: =I35/E35 | O35: =P35/E35 | P35: 2 | Q35: =E35-P35 | T35: 2 | U35: =T35/E35 | V35: =E35-T35 | W35: P1 | X35: ✅ | Z35: @杨忠谕 | AA35: @高宇新 | AB35: =AG35/AH35 | AC35: =AG35 | AD35: =E35-AC35 | AE35: =AF35/AG35 | AF35: =COUNTIFS('系统设置'!Q49:Q50,"✅") | AG35: =COUNTIFS('系统设置'!Q49:Q50,"✅")+COUNTIFS('系统设置'!Q49:Q50,"❌")+COUNTIFS('系统设置'!Q49:Q50,"Block") | AH35: 2 | AI35: =AF35 | AJ35: =AH35-AF35 | AK35: =AG35-AF35 | AL35: 字节-刘晓帝 PASS | AP35: 系统设置 | AQ35: =AH35-E35
B36: 无线网络 | C36: 【火山】待问题修复 | D36: 1 | E36: 1 | F36: =G36/E36 | G36: 1 | H36: =E36-G36 | I36: 1 | J36: =I36/E36 | K36: 04.17 04.20 FC 目前不支持 需要婉婷确认时间 04.20 @廖婉婷FC不支持，排期中https://meego.larkoffice.com/telematics/story/detail/7163979318 05.05 05.15缺少 FC 05.26，06.03 FC没下发 跟踪算法进度 0615 泽陆尽快起bug推进 0618 云端修复完成，完成开发 0622 研发名下无bug | O36: =P36/E36 | P36: 1 | Q36: =E36-P36 | T36: 1 | U36: =T36/E36 | V36: 1 | W36: P2 | Z36: @尹泽陆 | AA36: @樊晓天 | AB36: =AG36/AH36 | AC36: =AG36 | AD36: =E36-AC36 | AE36: =AF36/AG36 | AF36: =COUNTIFS('系统设置'!Q51,"✅") | AG36: =COUNTIFS('系统设置'!Q51,"✅")+COUNTIFS('系统设置'!Q51,"❌")+COUNTIFS('系统设置'!Q51,"Block") | AH36: 1 | AI36: =AF36 | AJ36: =AH36-AF36 | AK36: =AG36-AF36 | AL36: 字节-刘晓帝 | AP36: 系统设置 | AQ36: =AH36-E36
